Workbook

Sheet Leia-me
A1: GESTAO DE PECAS DO BRITADOR — GUIA RAPIDO DA PLANILHA
A3: ABA | B3: O QUE FAZ
A4: Dashboard | B4: Visao executiva: cards de indicadores e 6 graficos (valor por categoria, status de RCs, status de pedidos, cobertura de estoque, curva ABC e estoque parado). Tudo calculado por formula.
A5: Materiais | B5: Cadastro mestre das pecas do britador (45 itens de exemplo). Colunas de entrada em preto (codigo, nome, custo, saldo, min/max, localizacao, criticidade) e colunas calculadas (cobertura, giro, status, risco de ruptura, curva ABC).
A6: Fornecedores | B6: Cadastro dos fornecedores com lead time e indicadores de performance (OTIF, atrasos), calculados a partir da aba Pedidos.
A7: Movimentacoes | B7: Historico de entradas e saidas de estoque (6 meses de exemplo). Alimenta o consumo medio e o giro de estoque em Materiais.
A8: Requisicoes | B8: Controle de RCs (requisicoes de compra) com status (Pendente, Aguardando Aprovacao, Em Cotacao, Convertida).
A9: Pedidos | B9: Controle de OCs (pedidos de compra) com datas previstas/recebidas, status e atraso calculados automaticamente.
A10: Indicadores | B10: Aba de apoio: agrega os dados das demais abas nas tabelas que alimentam os graficos do Dashboard. Nao precisa editar.
A12: COMO ATUALIZAR OS DADOS
A13: 1. | B13: Adicione novas pecas na aba Materiais (proxima linha livre), preenchendo as colunas A ate K. As colunas L em diante sao formulas — copie-as da ultima linha para baixo.
A14: 2. | B14: Registre entradas e saidas de estoque na aba Movimentacoes.
A15: 3. | B15: Registre novas requisicoes e pedidos nas abas Requisicoes e Pedidos.
A16: 4. | B16: O Dashboard e a aba Indicadores recalculam automaticamente — nao exigem nenhuma acao manual.
A18: OBSERVACAO | B18: Os dados de materiais, fornecedores, movimentacoes, requisicoes e pedidos sao EXEMPLOS para demonstrar a estrutura e os indicadores. Substitua pelos dados reais da mineradora.

Sheet Dashboard
A1: DASHBOARD EXECUTIVO — GESTAO DE PECAS DO BRITADOR
A2: Mineradora — Manutencao Mecanica e Eletrica | Atualizado automaticamente ao abrir a planilha
A4: VALOR EM ESTOQUE | C4: TOTAL DE MATERIAIS | E4: MATERIAIS CRITICOS | G4: RISCO DE RUPTURA (ALTO) | I4: ESTOQUE PARADO (R$) | K4: PEDIDOS ATRASADOS
A5: =SUM(Materiais!P2:P46) -> 558435.5 | C5: =COUNTA(Materiais!A2:A46) -> 45 | E5: =COUNTIF(Materiais!K2:K46,"Critico") -> 17 | G5: =COUNTIF(Materiais!V2:V46,"Alto") -> 17 | I5: =SUMIF(Materiais!T2:T46,">=90",Materiais!P2:P46) -> 558435.5 | K5: =COUNTIF(Pedidos!L2:L31,"Atrasado") -> 13
A7: RC's PENDENTES | C7: PEDIDOS EM ABERTO | E7: LEAD TIME MEDIO | G7: GIRO MEDIO DE ESTOQUE | I7: % OTIF MEDIO | K7: COMPRAS EM ABERTO (R$)
A8: =COUNTIF(Requisicoes!F2:F31,"Pendente") -> 8 | C8: =COUNTIFS(Pedidos!L2:L31,"<>Recebido") -> 14 | E8: =ROUND(AVERAGE(Fornecedores!D2:D9),0)&" dias" -> 16 dias | G8: =ROUND(AVERAGE(Materiais!R2:R46),1)&"x/ano" -> 0x/ano | I8: =ROUND(AVERAGE(Fornecedores!H2:H9),3) -> 0.213 | K8: =SUMIF(Pedidos!L2:L31,"<>Recebido",Pedidos!I2:I31) -> 714853.2
A47: Fonte: abas Materiais, Fornecedores, Movimentacoes, Requisicoes e Pedidos. Indicadores calculados por formula (SUMIFS/COUNTIFS/INDEX-MATCH) na aba Indicadores. Dados de exemplo — substitua pelos dados reais da mineradora.

Sheet Materiais
A1: Codigo | B1: Nome do Material | C1: Categoria | D1: Unidade | E1: Fornecedor | F1: Custo Unitario (R$) | G1: Saldo Atual | H1: Estoque Minimo | I1: Estoque Maximo | J1: Localizacao | K1: Criticidade | L1: Lead Time (dias) | M1: Consumo Medio Mensal | N1: Consumo Medio Diario | O1: Ponto de Reposicao | P1: Valor em Estoque (R$) | Q1: Cobertura (dias) | R1: Giro Anual | S1: Ultima Movimentacao | T1: Dias sem Movimentacao | U1: Status Estoque | V1: Risco de Ruptura | W1: Valor Acumulado % | X1: Classe ABC
A2: 100002001 | B2: Mandibula Fixa do Britador | C2: Estrutural | D2: UN | E2: F002 | F2: 18500 | G2: 0 | H2: 1 | I2: 3 | J2: A-01-01 | K2: Critico | L2: =IFERROR(INDEX(Fornecedores!$D:$D,MATCH(E2,Fornecedores!$A:$A,0)),15) -> 30 | M2: =ROUND(SUMIFS(Movimentacoes!#REF!,Movimentacoes!#REF!,A2,Movimentacoes!#REF!,"Saida")/6,1) -> #REF! | N2: =ROUND(M2/30,2) -> #REF! | O2: =ROUND(H2+N2*L2,0) -> #REF! | P2: =G2*F2 -> 0 | Q2: =IFERROR(ROUND(G2/N2,1),0) -> 0 | R2: =IFERROR(ROUND((M2*12)/((G2+H2)/2),2),0) -> 0 | S2: =IFERROR(_xlfn.MAXIFS(Movimentacoes!#REF!,Movimentacoes!#REF!,A2),"") | T2: =IF(S2="",9999,TODAY()-S2) -> 9999 | U2: =IF(G2<=0,"Ruptura",IF(G2<H2,"Abaixo do Minimo",IF(G2<O2,"Ponto de Reposicao","Normal"))) -> Ruptura | V2: =IF(AND(K2="Critico",Q2<L2),"Alto",IF(Q2<L2,"Medio","Baixo")) -> Alto | W2: =SUMPRODUCT(($P$2:$P$46>=P2)*$P$2:$P$46)/SUM($P$2:$P$46) -> 1 | X2: =IF(W2<=0.7,"A",IF(W2<=0.9,"B","C")) -> C
A3: 100002002 | B3: Mandibula Movel do Britador | C3: Estrutural | D3: UN | E3: F002 | F3: 19800 | G3: 0 | H3: 1 | I3: 3 | J3: A-01-02 | K3: Critico | L3: =IFERROR(INDEX(Fornecedores!$D:$D,MATCH(E3,Fornecedores!$A:$A,0)),15) -> 30 | M3: =ROUND(SUMIFS(Movimentacoes!#REF!,Movimentacoes!#REF!,A3,Movimentacoes!#REF!,"Saida")/6,1) -> #REF! | N3: =ROUND(M3/30,2) -> #REF! | O3: =ROUND(H3+N3*L3,0) -> #REF! | P3: =G3*F3 -> 0 | Q3: =IFERROR(ROUND(G3/N3,1),0) -> 0 | R3: =IFERROR(ROUND((M3*12)/((G3+H3)/2),2),0) -> 0 | S3: =IFERROR(_xlfn.MAXIFS(Movimentacoes!#REF!,Movimentacoes!#REF!,A3),"") | T3: =IF(S3="",9999,TODAY()-S3) -> 9999 | U3: =IF(G3<=0,"Ruptura",IF(G3<H3,"Abaixo do Minimo",IF(G3<O3,"Ponto de Reposicao","Normal"))) -> Ruptura | V3: =IF(AND(K3="Critico",Q3<L3),"Alto",IF(Q3<L3,"Medio","Baixo")) -> Alto | W3: =SUMPRODUCT(($P$2:$P$46>=P3)*$P$2:$P$46)/SUM($P$2:$P$46) -> 1 | X3: =IF(W3<=0.7,"A",IF(W3<=0.9,"B","C")) -> C
A4: 100002003 | B4: Revestimento Concavo | C4: Revestimentos | D4: UN | E4: F002 | F4: 12400 | G4: 2 | H4: 2 | I4: 6 | J4: A-02-01 | K4: Critico | L4: =IFERROR(INDEX(Fornecedores!$D:$D,MATCH(E4,Fornecedores!$A:$A,0)),15) -> 30 | M4: =ROUND(SUMIFS(Movimentacoes!#REF!,Movimentacoes!#REF!,A4,Movimentacoes!#REF!,"Saida")/6,1) -> #REF! | N4: =ROUND(M4/30,2) -> #REF! | O4: =ROUND(H4+N4*L4,0) -> #REF! | P4: =G4*F4 -> 24800 | Q4: =IFERROR(ROUND(G4/N4,1),0) -> 0 | R4: =IFERROR(ROUND((M4*12)/((G4+H4)/2),2),0) -> 0 | S4: =IFERROR(_xlfn.MAXIFS(Movimentacoes!#REF!,Movimentacoes!#REF!,A4),"") | T4: =IF(S4="",9999,TODAY()-S4) -> 9999 | U4: =IF(G4<=0,"Ruptura",IF(G4<H4,"Abaixo do Minimo",IF(G4<O4,"Ponto de Reposicao","Normal"))) -> #REF! | V4: =IF(AND(K4="Critico",Q4<L4),"Alto",IF(Q4<L4,"Medio","Baixo")) -> Alto | W4: =SUMPRODUCT(($P$2:$P$46>=P4)*$P$2:$P$46)/SUM($P$2:$P$46) -> 0.62057301 | X4: =IF(W4<=0.7,"A",IF(W4<=0.9,"B","C")) -> A
A5: 100002004 | B5: Revestimento Manto | C5: Revestimentos | D5: UN | E5: F002 | F5: 11800 | G5: 4 | H5: 2 | I5: 6 | J5: A-02-02 | K5: Critico | L5: =IFERROR(INDEX(Fornecedores!$D:$D,MATCH(E5,Fornecedores!$A:$A,0)),15) -> 30 | M5: =ROUND(SUMIFS(Movimentacoes!#REF!,Movimentacoes!#REF!,A5,Movimentacoes!#REF!,"Saida")/6,1) -> #REF! | N5: =ROUND(M5/30,2) -> #REF! | O5: =ROUND(H5+N5*L5,0) -> #REF! | P5: =G5*F5 -> 47200 | Q5: =IFERROR(ROUND(G5/N5,1),0) -> 0 | R5: =IFERROR(ROUND((M5*12)/((G5+H5)/2),2),0) -> 0 | S5: =IFERROR(_xlfn.MAXIFS(Movimentacoes!#REF!,Movimentacoes!#REF!,A5),"") | T5: =IF(S5="",9999,TODAY()-S5) -> 9999 | U5: =IF(G5<=0,"Ruptura",IF(G5<H5,"Abaixo do Minimo",IF(G5<O5,"Ponto de Reposicao","Normal"))) -> #REF! | V5: =IF(AND(K5="Critico",Q5<L5),"Alto",IF(Q5<L5,"Medio","Baixo")) -> Alto | W5: =SUMPRODUCT(($P$2:$P$46>=P5)*$P$2:$P$46)/SUM($P$2:$P$46) -> 0.2886636 | X5: =IF(W5<=0.7,"A",IF(W5<=0.9,"B","C")) -> A
A6: 100002005 | B6: Chapa Blindada Lateral | C6: Revestimentos | D6: UN | E6: F003 | F6: 3450 | G6: 6 | H6: 3 | I6: 10 | J6: A-02-03 | K6: Nao Critico | L6: =IFERROR(INDEX(Fornecedores!$D:$D,MATCH(E6,Fornecedores!$A:$A,0)),15) -> 25 | M6: =ROUND(SUMIFS(Movimentacoes!#REF!,Movimentacoes!#REF!,A6,Movimentacoes!#REF!,"Saida")/6,1) -> #REF! | N6: =ROUND(M6/30,2) -> #REF! | O6: =ROUND(H6+N6*L6,0) -> #REF! | P6: =G6*F6 -> 20700 | Q6: =IFERROR(ROUND(G6/N6,1),0) -> 0 | R6: =IFERROR(ROUND((M6*12)/((G6+H6)/2),2),0) -> 0 | S6: =IFERROR(_xlfn.MAXIFS(Movimentacoes!#REF!,Movimentacoes!#REF!,A6),"") | T6: =IF(S6="",9999,TODAY()-S6) -> 9999 | U6: =IF(G6<=0,"Ruptura",IF(G6<H6,"Abaixo do Minimo",IF(G6<O6,"Ponto de Reposicao","Normal"))) -> #REF! | V6: =IF(AND(K6="Critico",Q6<L6),"Alto",IF(Q6<L6,"Medio","Baixo")) -> Medio | W6: =SUMPRODUCT(($P$2:$P$46>=P6)*$P$2:$P$46)/SUM($P$2:$P$46) -> 0.73671892 | X6: =IF(W6<=0.7,"A",IF(W6<=0.9,"B","C")) -> B
A7: 100002006 | B7: Chapa de Desgaste | C7: Revestimentos | D7: UN | E7: F003 | F7: 2870 | G7: 8 | H7: 3 | I7: 12 | J7: A-02-04 | K7: Nao Critico | L7: =IFERROR(INDEX(Fornecedores!$D:$D,MATCH(E7,Fornecedores!$A:$A,0)),15) -> 25 | M7: =ROUND(SUMIFS(Movimentacoes!#REF!,Movimentacoes!#REF!,A7,Movimentacoes!#REF!,"Saida")/6,1) -> #REF! | N7: =ROUND(M7/30,2) -> #REF! | O7: =ROUND(H7+N7*L7,0) -> #REF! | P7: =G7*F7 -> 22960 | Q7: =IFERROR(ROUND(G7/N7,1),0) -> 0 | R7: =IFERROR(ROUND((M7*12)/((G7+H7)/2),2),0) -> 0 | S7: =IFERROR(_xlfn.MAXIFS(Movimentacoes!#REF!,Movimentacoes!#REF!,A7),"") | T7: =IF(S7="",9999,TODAY()-S7) -> 9999 | U7: =IF(G7<=0,"Ruptura",IF(G7<H7,"Abaixo do Minimo",IF(G7<O7,"Ponto de Reposicao","Normal"))) -> #REF! | V7: =IF(AND(K7="Critico",Q7<L7),"Alto",IF(Q7<L7,"Medio","Baixo")) -> Medio | W7: =SUMPRODUCT(($P$2:$P$46>=P7)*$P$2:$P$46)/SUM($P$2:$P$46) -> 0.66168788 | X7: =IF(W7<=0.7,"A",IF(W7<=0.9,"B","C")) -> A
A8: 100002007 | B8: Placa de Impacto | C8: Revestimentos | D8: UN | E8: F003 | F8: 1980 | G8: 15 | H8: 4 | I8: 15 | J8: A-02-05 | K8: Nao Critico | L8: =IFERROR(INDEX(Fornecedores!$D:$D,MATCH(E8,Fornecedores!$A:$A,0)),15) -> 25 | M8: =ROUND(SUMIFS(Movimentacoes!#REF!,Movimentacoes!#REF!,A8,Movimentacoes!#REF!,"Saida")/6,1) -> #REF! | N8: =ROUND(M8/30,2) -> #REF! | O8: =ROUND(H8+N8*L8,0) -> #REF! | P8: =G8*F8 -> 29700 | Q8: =IFERROR(ROUND(G8/N8,1),0) -> 0 | R8: =IFERROR(ROUND((M8*12)/((G8+H8)/2),2),0) -> 0 | S8: =IFERROR(_xlfn.MAXIFS(Movimentacoes!#REF!,Movimentacoes!#REF!,A8),"") | T8: =IF(S8="",9999,TODAY()-S8) -> 9999 | U8: =IF(G8<=0,"Ruptura",IF(G8<H8,"Abaixo do Minimo",IF(G8<O8,"Ponto de Reposicao","Normal"))) -> #REF! | V8: =IF(AND(K8="Critico",Q8<L8),"Alto",IF(Q8<L8,"Medio","Baixo")) -> Medio | W8: =SUMPRODUCT(($P$2:$P$46>=P8)*$P$2:$P$46)/SUM($P$2:$P$46) -> 0.52593361 | X8: =IF(W8<=0.7,"A",IF(W8<=0.9,"B","C")) -> A
A9: 100002008 | B9: Eixo Excentrico | C9: Estrutural | D9: UN | E9: F002 | F9: 24500 | G9: 2 | H9: 1 | I9: 2 | J9: A-01-03 | K9: Critico | L9: =IFERROR(INDEX(Fornecedores!$D:$D,MATCH(E9,Fornecedores!$A:$A,0)),15) -> 30 | M9: =ROUND(SUMIFS(Movimentacoes!#REF!,Movimentacoes!#REF!,A9,Movimentacoes!#REF!,"Saida")/6,1) -> #REF! | N9: =ROUND(M9/30,2) -> #REF! | O9: =ROUND(H9+N9*L9,0) -> #REF! | P9: =G9*F9 -> 49000 | Q9: =IFERROR(ROUND(G9/N9,1),0) -> 0 | R9: =IFERROR(ROUND((M9*12)/((G9+H9)/2),2),0) -> 0 | S9: =IFERROR(_xlfn.MAXIFS(Movimentacoes!#REF!,Movimentacoes!#REF!,A9),"") | T9: =IF(S9="",9999,TODAY()-S9) -> 9999 | U9: =IF(G9<=0,"Ruptura",IF(G9<H9,"Abaixo do Minimo",IF(G9<O9,"Ponto de Reposicao","Normal"))) -> #REF! | V9: =IF(AND(K9="Critico",Q9<L9),"Alto",IF(Q9<L9,"Medio","Baixo")) -> Alto | W9: =SUMPRODUCT(($P$2:$P$46>=P9)*$P$2:$P$46)/SUM($P$2:$P$46) -> 0.20414175 | X9: =IF(W9<=0.7,"A",IF(W9<=0.9,"B","C")) -> A
A10: 100002009 | B10: Bucha de Bronze | C10: Estrutural | D10: UN | E10: F007 | F10: 1650 | G10: 17 | H10: 4 | I10: 12 | J10: A-01-04 | K10: Critico | L10: =IFERROR(INDEX(Fornecedores!$D:$D,MATCH(E10,Fornecedores!$A:$A,0)),15) -> 8 | M10: =ROUND(SUMIFS(Movimentacoes!#REF!,Movimentacoes!#REF!,A10,Movimentacoes!#REF!,"Saida")/6,1) -> #REF! | N10: =ROUND(M10/30,2) -> #REF! | O10: =ROUND(H10+N10*L10,0) -> #REF! | P10: =G10*F10 -> 28050 | Q10: =IFERROR(ROUND(G10/N10,1),0) -> 0 | R10: =IFERROR(ROUND((M10*12)/((G10+H10)/2),2),0) -> 0 | S10: =IFERROR(_xlfn.MAXIFS(Movimentacoes!#REF!,Movimentacoes!#REF!,A10),"") | T10: =IF(S10="",9999,TODAY()-S10) -> 9999 | U10: =IF(G10<=0,"Ruptura",IF(G10<H10,"Abaixo do Minimo",IF(G10<O10,"Ponto de Reposicao","Normal"))) -> #REF! | V10: =IF(AND(K10="Critico",Q10<L10),"Alto",IF(Q10<L10,"Medio","Baixo")) -> Alto | W10: =SUMPRODUCT(($P$2:$P$46>=P10)*$P$2:$P$46)/SUM($P$2:$P$46) -> 0.57616323 | X10: =IF(W10<=0.7,"A",IF(W10<=0.9,"B","C")) -> A
A11: 100002010 | B11: Bucha Excentrica | C11: Estrutural | D11: UN | E11: F007 | F11: 2150 | G11: 0 | H11: 3 | I11: 10 | J11: A-01-05 | K11: Critico | L11: =IFERROR(INDEX(Fornecedores!$D:$D,MATCH(E11,Fornecedores!$A:$A,0)),15) -> 8 | M11: =ROUND(SUMIFS(Movimentacoes!#REF!,Movimentacoes!#REF!,A11,Movimentacoes!#REF!,"Saida")/6,1) -> #REF! | N11: =ROUND(M11/30,2) -> #REF! | O11: =ROUND(H11+N11*L11,0) -> #REF! | P11: =G11*F11 -> 0 | Q11: =IFERROR(ROUND(G11/N11,1),0) -> 0 | R11: =IFERROR(ROUND((M11*12)/((G11+H11)/2),2),0) -> 0 | S11: =IFERROR(_xlfn.MAXIFS(Movimentacoes!#REF!,Movimentacoes!#REF!,A11),"") | T11: =IF(S11="",9999,TODAY()-S11) -> 9999 | U11: =IF(G11<=0,"Ruptura",IF(G11<H11,"Abaixo do Minimo",IF(G11<O11,"Ponto de Reposicao","Normal"))) -> Ruptura | V11: =IF(AND(K11="Critico",Q11<L11),"Alto",IF(Q11<L11,"Medio","Baixo")) -> Alto | W11: =SUMPRODUCT(($P$2:$P$46>=P11)*$P$2:$P$46)/SUM($P$2:$P$46) -> 1 | X11: =IF(W11<=0.7,"A",IF(W11<=0.9,"B","C")) -> C
A12: 100002011 | B12: Volante de Inercia | C12: Estrutural | D12: UN | E12: F002 | F12: 9800 | G12: 0 | H12: 1 | I12: 3 | J12: A-01-06 | K12: Nao Critico | L12: =IFERROR(INDEX(Fornecedores!$D:$D,MATCH(E12,Fornecedores!$A:$A,0)),15) -> 30 | M12: =ROUND(SUMIFS(Movimentacoes!#REF!,Movimentacoes!#REF!,A12,Movimentacoes!#REF!,"Saida")/6,1) -> #REF! | N12: =ROUND(M12/30,2) -> #REF! | O12: =ROUND(H12+N12*L12,0) -> #REF! | P12: =G12*F12 -> 0 | Q12: =IFERROR(ROUND(G12/N12,1),0) -> 0 | R12: =IFERROR(ROUND((M12*12)/((G12+H12)/2),2),0) -> 0 | S12: =IFERROR(_xlfn.MAXIFS(Movimentacoes!#REF!,Movimentacoes!#REF!,A12),"") | T12: =IF(S12="",9999,TODAY()-S12) -> 9999 | U12: =IF(G12<=0,"Ruptura",IF(G12<H12,"Abaixo do Minimo",IF(G12<O12,"Ponto de Reposicao","Normal"))) -> Ruptura | V12: =IF(AND(K12="Critico",Q12<L12),"Alto",IF(Q12<L12,"Medio","Baixo")) -> Medio | W12: =SUMPRODUCT(($P$2:$P$46>=P12)*$P$2:$P$46)/SUM($P$2:$P$46) -> 1 | X12: =IF(W12<=0.7,"A",IF(W12<=0.9,"B","C")) -> C
A13: 100002012 | B13: Grelha Vibratoria | C13: Estrutural | D13: UN | E13: F003 | F13: 5400 | G13: 1 | H13: 1 | I13: 4 | J13: A-01-07 | K13: Nao Critico | L13: =IFERROR(INDEX(Fornecedores!$D:$D,MATCH(E13,Fornecedores!$A:$A,0)),15) -> 25 | M13: =ROUND(SUMIFS(Movimentacoes!#REF!,Movimentacoes!#REF!,A13,Movimentacoes!#REF!,"Saida")/6,1) -> #REF! | N13: =ROUND(M13/30,2) -> #REF! | O13: =ROUND(H13+N13*L13,0) -> #REF! | P13: =G13*F13 -> 5400 | Q13: =IFERROR(ROUND(G13/N13,1),0) -> 0 | R13: =IFERROR(ROUND((M13*12)/((G13+H13)/2),2),0) -> 0 | S13: =IFERROR(_xlfn.MAXIFS(Movimentacoes!#REF!,Movimentacoes!#REF!,A13),"") | T13: =IF(S13="",9999,TODAY()-S13) -> 9999 | U13: =IF(G13<=0,"Ruptura",IF(G13<H13,"Abaixo do Minimo",IF(G13<O13,"Ponto de Reposicao","Normal"))) -> #REF! | V13: =IF(AND(K13="Critico",Q13<L13),"Alto",IF(Q13<L13,"Medio","Baixo")) -> Medio | W13: =SUMPRODUCT(($P$2:$P$46>=P13)*$P$2:$P$46)/SUM($P$2:$P$46) -> 0.92041068 | X13: =IF(W13<=0.7,"A",IF(W13<=0.9,"B","C")) -> C
... A46: 100009005 | B46: Anel de Vedacao O-ring | C46: Fixacao | D46: UN | E46: F008 | F46: 8.9 | G46: 350 | H46: 50 | I46: 250 | J46: D-02-05 | K46: Nao Critico | L46: =IFERROR(INDEX(Fornecedores!$D:$D,MATCH(E46,Fornecedores!$A:$A,0)),15) -> 5 | M46: =ROUND(SUMIFS(Movimentacoes!#REF!,Movimentacoes!#REF!,A46,Movimentacoes!#REF!,"Saida")/6,1) -> #REF! | N46: =ROUND(M46/30,2) -> #REF! | O46: =ROUND(H46+N46*L46,0) -> #REF! | P46: =G46*F46 -> 3115 | Q46: =IFERROR(ROUND(G46/N46,1),0) -> 0 | R46: =IFERROR(ROUND((M46*12)/((G46+H46)/2),2),0) -> 0 | S46: =IFERROR(_xlfn.MAXIFS(Movimentacoes!#REF!,Movimentacoes!#REF!,A46),"") | T46: =IF(S46="",9999,TODAY()-S46) -> 9999 | U46: =IF(G46<=0,"Ruptura",IF(G46<H46,"Abaixo do Minimo",IF(G46<O46,"Ponto de Reposicao","Normal"))) -> #REF! | V46: =IF(AND(K46="Critico",Q46<L46),"Alto",IF(Q46<L46,"Medio","Baixo")) -> Medio | W46: =SUMPRODUCT(($P$2:$P$46>=P46)*$P$2:$P$46)/SUM($P$2:$P$46) -> 0.96860425 | X46: =IF(W46<=0.7,"A",IF(W46<=0.9,"B","C")) -> C

Sheet Fornecedores
A1: Codigo | B1: Nome do Fornecedor | C1: Contato | D1: Lead Time Medio (dias) | E1: Total de Pedidos | F1: Pedidos Recebidos | G1: Entregas no Prazo | H1: % OTIF | I1: Pedidos Atrasados (Abertos) | J1: Performance
A2: F001 | B2: SKF do Brasil Ltda | C2: (11) 4002-8888 | D2: 15 | E2: =COUNTIF(Pedidos!$E:$E,A2) -> 2 | F2: =COUNTIFS(Pedidos!$E:$E,A2,Pedidos!$L:$L,"Recebido") -> 1 | G2: =COUNTIFS(Pedidos!$E:$E,A2,Pedidos!$M:$M,"No Prazo") -> 0 | H2: =IFERROR(G2/F2,0) -> 0 | I2: =COUNTIFS(Pedidos!$E:$E,A2,Pedidos!$L:$L,"Atrasado") -> 1 | J2: =IF(H2>=0.95,"Excelente",IF(H2>=0.85,"Bom",IF(H2>=0.7,"Regular","Ruim"))) -> Ruim
A3: F002 | B3: Metso Outotec Brasil | C3: (31) 3298-1000 | D3: 30 | E3: =COUNTIF(Pedidos!$E:$E,A3) -> 4 | F3: =COUNTIFS(Pedidos!$E:$E,A3,Pedidos!$L:$L,"Recebido") -> 1 | G3: =COUNTIFS(Pedidos!$E:$E,A3,Pedidos!$M:$M,"No Prazo") -> 0 | H3: =IFERROR(G3/F3,0) -> 0 | I3: =COUNTIFS(Pedidos!$E:$E,A3,Pedidos!$L:$L,"Atrasado") -> 2 | J3: =IF(H3>=0.95,"Excelente",IF(H3>=0.85,"Bom",IF(H3>=0.7,"Regular","Ruim"))) -> Ruim
A4: F003 | B4: Sandvik Mining Brasil | C4: (11) 5185-4000 | D4: 25 | E4: =COUNTIF(Pedidos!$E:$E,A4) -> 2 | F4: =COUNTIFS(Pedidos!$E:$E,A4,Pedidos!$L:$L,"Recebido") -> 2 | G4: =COUNTIFS(Pedidos!$E:$E,A4,Pedidos!$M:$M,"No Prazo") -> 0 | H4: =IFERROR(G4/F4,0) -> 0 | I4: =COUNTIFS(Pedidos!$E:$E,A4,Pedidos!$L:$L,"Atrasado") -> 0 | J4: =IF(H4>=0.95,"Excelente",IF(H4>=0.85,"Bom",IF(H4>=0.7,"Regular","Ruim"))) -> Ruim
A5: F004 | B5: WEG Equipamentos S.A. | C5: (47) 3276-4000 | D5: 12 | E5: =COUNTIF(Pedidos!$E:$E,A5) -> 8 | F5: =COUNTIFS(Pedidos!$E:$E,A5,Pedidos!$L:$L,"Recebido") -> 2 | G5: =COUNTIFS(Pedidos!$E:$E,A5,Pedidos!$M:$M,"No Prazo") -> 1 | H5: =IFERROR(G5/F5,0) -> 0.5 | I5: =COUNTIFS(Pedidos!$E:$E,A5,Pedidos!$L:$L,"Atrasado") -> 6 | J5: =IF(H5>=0.95,"Excelente",IF(H5>=0.85,"Bom",IF(H5>=0.7,"Regular","Ruim"))) -> Ruim
A6: F005 | B6: Gates Correias Industriais | C6: (19) 3876-5500 | D6: 10 | E6: =COUNTIF(Pedidos!$E:$E,A6) -> 2 | F6: =COUNTIFS(Pedidos!$E:$E,A6,Pedidos!$L:$L,"Recebido") -> 1 | G6: =COUNTIFS(Pedidos!$E:$E,A6,Pedidos!$M:$M,"No Prazo") -> 0 | H6: =IFERROR(G6/F6,0) -> 0 | I6: =COUNTIFS(Pedidos!$E:$E,A6,Pedidos!$L:$L,"Atrasado") -> 1 | J6: =IF(H6>=0.95,"Excelente",IF(H6>=0.85,"Bom",IF(H6>=0.7,"Regular","Ruim"))) -> Ruim
A7: F006 | B7: Bosch Rexroth Brasil | C7: (11) 2465-8500 | D7: 20 | E7: =COUNTIF(Pedidos!$E:$E,A7) -> 2 | F7: =COUNTIFS(Pedidos!$E:$E,A7,Pedidos!$L:$L,"Recebido") -> 2 | G7: =COUNTIFS(Pedidos!$E:$E,A7,Pedidos!$M:$M,"No Prazo") -> 1 | H7: =IFERROR(G7/F7,0) -> 0.5 | I7: =COUNTIFS(Pedidos!$E:$E,A7,Pedidos!$L:$L,"Atrasado") -> 0 | J7: =IF(H7>=0.95,"Excelente",IF(H7>=0.85,"Bom",IF(H7>=0.7,"Regular","Ruim"))) -> Ruim
A8: F007 | B8: Rolamentos ABC Ltda | C8: (11) 3311-2200 | D8: 8 | E8: =COUNTIF(Pedidos!$E:$E,A8) -> 6 | F8: =COUNTIFS(Pedidos!$E:$E,A8,Pedidos!$L:$L,"Recebido") -> 4 | G8: =COUNTIFS(Pedidos!$E:$E,A8,Pedidos!$M:$M,"No Prazo") -> 2 | H8: =IFERROR(G8/F8,0) -> 0.5 | I8: =COUNTIFS(Pedidos!$E:$E,A8,Pedidos!$L:$L,"Atrasado") -> 2 | J8: =IF(H8>=0.95,"Excelente",IF(H8>=0.85,"Bom",IF(H8>=0.7,"Regular","Ruim"))) -> Ruim
A9: F008 | B9: Ferragens Industrial XYZ | C9: (31) 3221-7700 | D9: 5 | E9: =COUNTIF(Pedidos!$E:$E,A9) -> 6 | F9: =COUNTIFS(Pedidos!$E:$E,A9,Pedidos!$L:$L,"Recebido") -> 5 | G9: =COUNTIFS(Pedidos!$E:$E,A9,Pedidos!$M:$M,"No Prazo") -> 1 | H9: =IFERROR(G9/F9,0) -> 0.2 | I9: =COUNTIFS(Pedidos!$E:$E,A9,Pedidos!$L:$L,"Atrasado") -> 1 | J9: =IF(H9>=0.95,"Excelente",IF(H9>=0.85,"Bom",IF(H9>=0.7,"Regular","Ruim"))) -> Ruim

Sheet Movimentacoes
A1: Data | B1: Documento Material | C1: Tipo Movimento | D1: Material | E1: Descricao Material | F1: Centro | G1: Deposito | H1: Quantidade | I1: UM | J1: Valor Unitario | K1: Valor Total | L1: Referencia
A2: 46024 | B2: 500000001 | C2: 101 | D2: 100002001 | E2: Mandibula Fixa do Britador | F2: 1000 | G2: ALM1 | H2: 5 | I2: UN | J2: 18500 | K2: 92500 | L2: Pedido 450001000
A3: 46039 | B3: 500000002 | C3: 261 | D3: 100002001 | E3: Mandibula Fixa do Britador | F3: 1000 | G3: ALM1 | H3: -2 | I3: UN | J3: 18500 | K3: -37000 | L3: OS 70001000
A4: 46025 | B4: 500000003 | C4: 101 | D4: 100002002 | E4: Mandibula Movel do Britador | F4: 1000 | G4: ALM1 | H4: 5 | I4: UN | J4: 19800 | K4: 99000 | L4: Pedido 450001001
A5: 46040 | B5: 500000004 | C5: 261 | D5: 100002002 | E5: Mandibula Movel do Britador | F5: 1000 | G5: ALM1 | H5: -2 | I5: UN | J5: 19800 | K5: -39600 | L5: OS 70001001
A6: 46026 | B6: 500000005 | C6: 101 | D6: 100002003 | E6: Revestimento Concavo | F6: 1000 | G6: ALM1 | H6: 5 | I6: UN | J6: 12400 | K6: 62000 | L6: Pedido 450001002
A7: 46041 | B7: 500000006 | C7: 261 | D7: 100002003 | E7: Revestimento Concavo | F7: 1000 | G7: ALM1 | H7: -2 | I7: UN | J7: 12400 | K7: -24800 | L7: OS 70001002
A8: 46027 | B8: 500000007 | C8: 101 | D8: 100002004 | E8: Revestimento Manto | F8: 1000 | G8: ALM1 | H8: 5 | I8: UN | J8: 11800 | K8: 59000 | L8: Pedido 450001003
A9: 46042 | B9: 500000008 | C9: 261 | D9: 100002004 | E9: Revestimento Manto | F9: 1000 | G9: ALM1 | H9: -2 | I9: UN | J9: 11800 | K9: -23600 | L9: OS 70001003
A10: 46028 | B10: 500000009 | C10: 101 | D10: 100002005 | E10: Chapa Blindada Lateral | F10: 1000 | G10: ALM1 | H10: 5 | I10: UN | J10: 3450 | K10: 17250 | L10: Pedido 450001004
A11: 46043 | B11: 500000010 | C11: 261 | D11: 100002005 | E11: Chapa Blindada Lateral | F11: 1000 | G11: ALM1 | H11: -2 | I11: UN | J11: 3450 | K11: -6900 | L11: OS 70001004
A12: 46029 | B12: 500000011 | C12: 101 | D12: 100002006 | E12: Chapa de Desgaste | F12: 1000 | G12: ALM1 | H12: 5 | I12: UN | J12: 2870 | K12: 14350 | L12: Pedido 450001005
A13: 46044 | B13: 500000012 | C13: 261 | D13: 100002006 | E13: Chapa de Desgaste | F13: 1000 | G13: ALM1 | H13: -2 | I13: UN | J13: 2870 | K13: -5740 | L13: OS 70001005
... A91: 46083 | B91: 500000090 | C91: 261 | D91: 100009005 | E91: Anel de Vedacao O-ring | F91: 1000 | G91: ALM1 | H91: -2 | I91: UN | J91: 8.9 | K91: -17.8 | L91: OS 70001044

Sheet Requisicoes
A1: Codigo Material | B1: Nome do Material | C1: Numero RC | D1: Data | E1: Quantidade | F1: Status | G1: Dias em Aberto
A2: 100002001 | B2: =IFERROR(INDEX(Materiais!$B:$B,MATCH(A2,Materiais!$A:$A,0)),"") -> Mandibula Fixa do Britador | C2: RC450002300 | D2: 46199 | E2: 8 | F2: Convertida | G2: =IF(F2="Convertida","-",TODAY()-D2) -> -
A3: 100002002 | B3: =IFERROR(INDEX(Materiais!$B:$B,MATCH(A3,Materiais!$A:$A,0)),"") -> Mandibula Movel do Britador | C3: RC450002301 | D3: 46207 | E3: 4 | F3: Convertida | G3: =IF(F3="Convertida","-",TODAY()-D3) -> -
A4: 100002003 | B4: =IFERROR(INDEX(Materiais!$B:$B,MATCH(A4,Materiais!$A:$A,0)),"") -> Revestimento Concavo | C4: RC450002302 | D4: 46244 | E4: 3 | F4: Em Cotacao | G4: =IF(F4="Convertida","-",TODAY()-D4) -> 13
A5: 100002004 | B5: =IFERROR(INDEX(Materiais!$B:$B,MATCH(A5,Materiais!$A:$A,0)),"") -> Revestimento Manto | C5: RC450002303 | D5: 46199 | E5: 2 | F5: Aguardando Aprovacao | G5: =IF(F5="Convertida","-",TODAY()-D5) -> 58
A6: 100002005 | B6: =IFERROR(INDEX(Materiais!$B:$B,MATCH(A6,Materiais!$A:$A,0)),"") -> Chapa Blindada Lateral | C6: RC450002304 | D6: 46218 | E6: 8 | F6: Convertida | G6: =IF(F6="Convertida","-",TODAY()-D6) -> -
A7: 100002006 | B7: =IFERROR(INDEX(Materiais!$B:$B,MATCH(A7,Materiais!$A:$A,0)),"") -> Chapa de Desgaste | C7: RC450002305 | D7: 46221 | E7: 2 | F7: Pendente | G7: =IF(F7="Convertida","-",TODAY()-D7) -> 36
A8: 100002007 | B8: =IFERROR(INDEX(Materiais!$B:$B,MATCH(A8,Materiais!$A:$A,0)),"") -> Placa de Impacto | C8: RC450002306 | D8: 46146 | E8: 4 | F8: Pendente | G8: =IF(F8="Convertida","-",TODAY()-D8) -> 111
A9: 100002008 | B9: =IFERROR(INDEX(Materiais!$B:$B,MATCH(A9,Materiais!$A:$A,0)),"") -> Eixo Excentrico | C9: RC450002307 | D9: 46241 | E9: 8 | F9: Em Cotacao | G9: =IF(F9="Convertida","-",TODAY()-D9) -> 16
A10: 100002009 | B10: =IFERROR(INDEX(Materiais!$B:$B,MATCH(A10,Materiais!$A:$A,0)),"") -> Bucha de Bronze | C10: RC450002308 | D10: 46208 | E10: 5 | F10: Pendente | G10: =IF(F10="Convertida","-",TODAY()-D10) -> 49
A11: 100002010 | B11: =IFERROR(INDEX(Materiais!$B:$B,MATCH(A11,Materiais!$A:$A,0)),"") -> Bucha Excentrica | C11: RC450002309 | D11: 46142 | E11: 8 | F11: Convertida | G11: =IF(F11="Convertida","-",TODAY()-D11) -> -
A12: 100002011 | B12: =IFERROR(INDEX(Materiais!$B:$B,MATCH(A12,Materiais!$A:$A,0)),"") -> Volante de Inercia | C12: RC450002310 | D12: 46194 | E12: 2 | F12: Convertida | G12: =IF(F12="Convertida","-",TODAY()-D12) -> -
A13: 100002012 | B13: =IFERROR(INDEX(Materiais!$B:$B,MATCH(A13,Materiais!$A:$A,0)),"") -> Grelha Vibratoria | C13: RC450002311 | D13: 46182 | E13: 5 | F13: Convertida | G13: =IF(F13="Convertida","-",TODAY()-D13) -> -
... A32: 100005005 | B32: =IFERROR(INDEX(Materiais!$B:$B,MATCH(A32,Materiais!$A:$A,0)),"") -> Sensor de Temperatura | C32: RC450002329 | D32: 46151 | E32: 4 | F32: Pendente | G32: =IF(F32="Convertida","-",TODAY()-D32) -> 106

Sheet Pedidos
A1: Codigo Material | B1: Nome do Material | C1: Numero OC | D1: Data Emissao | E1: Fornecedor (Cod) | F1: Nome do Fornecedor | G1: Quantidade | H1: Valor Unitario (R$) | I1: Valor Total (R$) | J1: Data Prevista | K1: Data Recebimento | L1: Status | M1: Situacao Entrega | N1: Dias de Atraso
A2: 100002001 | B2: =IFERROR(INDEX(Materiais!$B:$B,MATCH(A2,Materiais!$A:$A,0)),"") -> Mandibula Fixa do Britador | C2: 457000 | D2: 46178 | E2: F002 | F2: =IFERROR(INDEX(Fornecedores!$B:$B,MATCH(E2,Fornecedores!$A:$A,0)),"") -> Metso Outotec Brasil | G2: 3 | H2: =IFERROR(INDEX(Materiais!$F:$F,MATCH(A2,Materiais!$A:$A,0)),0) -> 18500 | I2: =G2*H2 -> 55500 | J2: 46208 | K2: 46220 | L2: =IF(K2<>"","Recebido",IF(TODAY()>J2,"Atrasado","Em Transito")) -> Recebido | M2: =IF(K2="","-",IF(K2<=J2,"No Prazo","Atrasado")) -> Atrasado | N2: =IF(K2<>"",MAX(0,K2-J2),IF(TODAY()>J2,TODAY()-J2,0)) -> 12
A3: 100002004 | B3: =IFERROR(INDEX(Materiais!$B:$B,MATCH(A3,Materiais!$A:$A,0)),"") -> Revestimento Manto | C3: 457001 | D3: 46171 | E3: F002 | F3: =IFERROR(INDEX(Fornecedores!$B:$B,MATCH(E3,Fornecedores!$A:$A,0)),"") -> Metso Outotec Brasil | G3: 4 | H3: =IFERROR(INDEX(Materiais!$F:$F,MATCH(A3,Materiais!$A:$A,0)),0) -> 11800 | I3: =G3*H3 -> 47200 | J3: 46201 | L3: =IF(K3<>"","Recebido",IF(TODAY()>J3,"Atrasado","Em Transito")) -> Atrasado | M3: =IF(K3="","-",IF(K3<=J3,"No Prazo","Atrasado")) -> - | N3: =IF(K3<>"",MAX(0,K3-J3),IF(TODAY()>J3,TODAY()-J3,0)) -> 56
A4: 100002007 | B4: =IFERROR(INDEX(Materiais!$B:$B,MATCH(A4,Materiais!$A:$A,0)),"") -> Placa de Impacto | C4: 457002 | D4: 46159 | E4: F003 | F4: =IFERROR(INDEX(Fornecedores!$B:$B,MATCH(E4,Fornecedores!$A:$A,0)),"") -> Sandvik Mining Brasil | G4: 4 | H4: =IFERROR(INDEX(Materiais!$F:$F,MATCH(A4,Materiais!$A:$A,0)),0) -> 1980 | I4: =G4*H4 -> 7920 | J4: 46184 | K4: 46191 | L4: =IF(K4<>"","Recebido",IF(TODAY()>J4,"Atrasado","Em Transito")) -> Recebido | M4: =IF(K4="","-",IF(K4<=J4,"No Prazo","Atrasado")) -> Atrasado | N4: =IF(K4<>"",MAX(0,K4-J4),IF(TODAY()>J4,TODAY()-J4,0)) -> 7
A5: 100002010 | B5: =IFERROR(INDEX(Materiais!$B:$B,MATCH(A5,Materiais!$A:$A,0)),"") -> Bucha Excentrica | C5: 457003 | D5: 46187 | E5: F007 | F5: =IFERROR(INDEX(Fornecedores!$B:$B,MATCH(E5,Fornecedores!$A:$A,0)),"") -> Rolamentos ABC Ltda | G5: 10 | H5: =IFERROR(INDEX(Materiais!$F:$F,MATCH(A5,Materiais!$A:$A,0)),0) -> 2150 | I5: =G5*H5 -> 21500 | J5: 46195 | K5: 46195 | L5: =IF(K5<>"","Recebido",IF(TODAY()>J5,"Atrasado","Em Transito")) -> Recebido | M5: =IF(K5="","-",IF(K5<=J5,"No Prazo","Atrasado")) -> No Prazo | N5: =IF(K5<>"",MAX(0,K5-J5),IF(TODAY()>J5,TODAY()-J5,0)) -> 0
A6: 100002356 | B6: =IFERROR(INDEX(Materiais!$B:$B,MATCH(A6,Materiais!$A:$A,0)),"") -> Rolamento 6205 | C6: 457004 | D6: 46115 | E6: F007 | F6: =IFERROR(INDEX(Fornecedores!$B:$B,MATCH(E6,Fornecedores!$A:$A,0)),"") -> Rolamentos ABC Ltda | G6: 3 | H6: =IFERROR(INDEX(Materiais!$F:$F,MATCH(A6,Materiais!$A:$A,0)),0) -> 145 | I6: =G6*H6 -> 435 | J6: 46123 | L6: =IF(K6<>"","Recebido",IF(TODAY()>J6,"Atrasado","Em Transito")) -> Atrasado | M6: =IF(K6="","-",IF(K6<=J6,"No Prazo","Atrasado")) -> - | N6: =IF(K6<>"",MAX(0,K6-J6),IF(TODAY()>J6,TODAY()-J6,0)) -> 134
A7: 100002359 | B7: =IFERROR(INDEX(Materiais!$B:$B,MATCH(A7,Materiais!$A:$A,0)),"") -> Rolamento Esferico 22318 | C7: 457005 | D7: 46133 | E7: F001 | F7: =IFERROR(INDEX(Fornecedores!$B:$B,MATCH(E7,Fornecedores!$A:$A,0)),"") -> SKF do Brasil Ltda | G7: 5 | H7: =IFERROR(INDEX(Materiais!$F:$F,MATCH(A7,Materiais!$A:$A,0)),0) -> 1240 | I7: =G7*H7 -> 6200 | J7: 46148 | L7: =IF(K7<>"","Recebido",IF(TODAY()>J7,"Atrasado","Em Transito")) -> Atrasado | M7: =IF(K7="","-",IF(K7<=J7,"No Prazo","Atrasado")) -> - | N7: =IF(K7<>"",MAX(0,K7-J7),IF(TODAY()>J7,TODAY()-J7,0)) -> 109
A8: 100003001 | B8: =IFERROR(INDEX(Materiais!$B:$B,MATCH(A8,Materiais!$A:$A,0)),"") -> Correia Transportadora B-1200 | C8: 457006 | D8: 46227 | E8: F005 | F8: =IFERROR(INDEX(Fornecedores!$B:$B,MATCH(E8,Fornecedores!$A:$A,0)),"") -> Gates Correias Industriais | G8: 3 | H8: =IFERROR(INDEX(Materiais!$F:$F,MATCH(A8,Materiais!$A:$A,0)),0) -> 320 | I8: =G8*H8 -> 960 | J8: 46237 | L8: =IF(K8<>"","Recebido",IF(TODAY()>J8,"Atrasado","Em Transito")) -> Atrasado | M8: =IF(K8="","-",IF(K8<=J8,"No Prazo","Atrasado")) -> - | N8: =IF(K8<>"",MAX(0,K8-J8),IF(TODAY()>J8,TODAY()-J8,0)) -> 20
A9: 100003004 | B9: =IFERROR(INDEX(Materiais!$B:$B,MATCH(A9,Materiais!$A:$A,0)),"") -> Polia Movida | C9: 457007 | D9: 46177 | E9: F004 | F9: =IFERROR(INDEX(Fornecedores!$B:$B,MATCH(E9,Fornecedores!$A:$A,0)),"") -> WEG Equipamentos S.A. | G9: 8 | H9: =IFERROR(INDEX(Materiais!$F:$F,MATCH(A9,Materiais!$A:$A,0)),0) -> 2180 | I9: =G9*H9 -> 17440 | J9: 46189 | K9: 46189 | L9: =IF(K9<>"","Recebido",IF(TODAY()>J9,"Atrasado","Em Transito")) -> Recebido | M9: =IF(K9="","-",IF(K9<=J9,"No Prazo","Atrasado")) -> No Prazo | N9: =IF(K9<>"",MAX(0,K9-J9),IF(TODAY()>J9,TODAY()-J9,0)) -> 0
A10: 100005001 | B10: =IFERROR(INDEX(Materiais!$B:$B,MATCH(A10,Materiais!$A:$A,0)),"") -> Motor Eletrico 150cv | C10: 457008 | D10: 46221 | E10: F004 | F10: =IFERROR(INDEX(Fornecedores!$B:$B,MATCH(E10,Fornecedores!$A:$A,0)),"") -> WEG Equipamentos S.A. | G10: 7 | H10: =IFERROR(INDEX(Materiais!$F:$F,MATCH(A10,Materiais!$A:$A,0)),0) -> 32500 | I10: =G10*H10 -> 227500 | J10: 46233 | L10: =IF(K10<>"","Recebido",IF(TODAY()>J10,"Atrasado","Em Transito")) -> Atrasado | M10: =IF(K10="","-",IF(K10<=J10,"No Prazo","Atrasado")) -> - | N10: =IF(K10<>"",MAX(0,K10-J10),IF(TODAY()>J10,TODAY()-J10,0)) -> 24
A11: 100005004 | B11: =IFERROR(INDEX(Materiais!$B:$B,MATCH(A11,Materiais!$A:$A,0)),"") -> Sensor de Vibracao | C11: 457009 | D11: 46192 | E11: F004 | F11: =IFERROR(INDEX(Fornecedores!$B:$B,MATCH(E11,Fornecedores!$A:$A,0)),"") -> WEG Equipamentos S.A. | G11: 6 | H11: =IFERROR(INDEX(Materiais!$F:$F,MATCH(A11,Materiais!$A:$A,0)),0) -> 1350 | I11: =G11*H11 -> 8100 | J11: 46204 | L11: =IF(K11<>"","Recebido",IF(TODAY()>J11,"Atrasado","Em Transito")) -> Atrasado | M11: =IF(K11="","-",IF(K11<=J11,"No Prazo","Atrasado")) -> - | N11: =IF(K11<>"",MAX(0,K11-J11),IF(TODAY()>J11,TODAY()-J11,0)) -> 53
A12: 100005007 | B12: =IFERROR(INDEX(Materiais!$B:$B,MATCH(A12,Materiais!$A:$A,0)),"") -> Contator Tripolar | C12: 457010 | D12: 46179 | E12: F004 | F12: =IFERROR(INDEX(Fornecedores!$B:$B,MATCH(E12,Fornecedores!$A:$A,0)),"") -> WEG Equipamentos S.A. | G12: 9 | H12: =IFERROR(INDEX(Materiais!$F:$F,MATCH(A12,Materiais!$A:$A,0)),0) -> 340 | I12: =G12*H12 -> 3060 | J12: 46191 | L12: =IF(K12<>"","Recebido",IF(TODAY()>J12,"Atrasado","Em Transito")) -> Atrasado | M12: =IF(K12="","-",IF(K12<=J12,"No Prazo","Atrasado")) -> - | N12: =IF(K12<>"",MAX(0,K12-J12),IF(TODAY()>J12,TODAY()-J12,0)) -> 66
A13: 100006003 | B13: =IFERROR(INDEX(Materiais!$B:$B,MATCH(A13,Materiais!$A:$A,0)),"") -> Mangueira Hidraulica 1 polegada | C13: 457011 | D13: 46146 | E13: F006 | F13: =IFERROR(INDEX(Fornecedores!$B:$B,MATCH(E13,Fornecedores!$A:$A,0)),"") -> Bosch Rexroth Brasil | G13: 8 | H13: =IFERROR(INDEX(Materiais!$F:$F,MATCH(A13,Materiais!$A:$A,0)),0) -> 85 | I13: =G13*H13 -> 680 | J13: 46166 | K13: 46178 | L13: =IF(K13<>"","Recebido",IF(TODAY()>J13,"Atrasado","Em Transito")) -> Recebido | M13: =IF(K13="","-",IF(K13<=J13,"No Prazo","Atrasado")) -> Atrasado | N13: =IF(K13<>"",MAX(0,K13-J13),IF(TODAY()>J13,TODAY()-J13,0)) -> 12
A14: 100007002 | B14: =IFERROR(INDEX(Materiais!$B:$B,MATCH(A14,Materiais!$A:$A,0)),"") -> Filtro de Oleo Lubrificante | C14: 457012 | D14: 46157 | E14: F007 | F14: =IFERROR(INDEX(Fornecedores!$B:$B,MATCH(E14,Fornecedores!$A:$A,0)),"") -> Rolamentos ABC Ltda | G14: 9 | H14: =IFERROR(INDEX(Materiais!$F:$F,MATCH(A14,Materiais!$A:$A,0)),0) -> 95 | I14: =G14*H14 -> 855 | J14: 46165 | K14: 46165 | L14: =IF(K14<>"","Recebido",IF(TODAY()>J14,"Atrasado","Em Transito")) -> Recebido | M14: =IF(K14="","-",IF(K14<=J14,"No Prazo","Atrasado")) -> No Prazo | N14: =IF(K14<>"",MAX(0,K14-J14),IF(TODAY()>J14,TODAY()-J14,0)) -> 0
A15: 100008002 | B15: =IFERROR(INDEX(Materiais!$B:$B,MATCH(A15,Materiais!$A:$A,0)),"") -> Graxa Industrial EP2 | C15: 457013 | D15: 46203 | E15: F008 | F15: =IFERROR(INDEX(Fornecedores!$B:$B,MATCH(E15,Fornecedores!$A:$A,0)),"") -> Ferragens Industrial XYZ | G15: 5 | H15: =IFERROR(INDEX(Materiais!$F:$F,MATCH(A15,Materiais!$A:$A,0)),0) -> 32 | I15: =G15*H15 -> 160 | J15: 46208 | K15: 46211 | L15: =IF(K15<>"","Recebido",IF(TODAY()>J15,"Atrasado","Em Transito")) -> Recebido | M15: =IF(K15="","-",IF(K15<=J15,"No Prazo","Atrasado")) -> Atrasado | N15: =IF(K15<>"",MAX(0,K15-J15),IF(TODAY()>J15,TODAY()-J15,0)) -> 3
A16: 100009003 | B16: =IFERROR(INDEX(Materiais!$B:$B,MATCH(A16,Materiais!$A:$A,0)),"") -> Arruela de Pressao M24 | C16: 457014 | D16: 46183 | E16: F008 | F16: =IFERROR(INDEX(Fornecedores!$B:$B,MATCH(E16,Fornecedores!$A:$A,0)),"") -> Ferragens Industrial XYZ | G16: 10 | H16: =IFERROR(INDEX(Materiais!$F:$F,MATCH(A16,Materiais!$A:$A,0)),0) -> 2.2 | I16: =G16*H16 -> 22 | J16: 46188 | K16: 46188 | L16: =IF(K16<>"","Recebido",IF(TODAY()>J16,"Atrasado","Em Transito")) -> Recebido | M16: =IF(K16="","-",IF(K16<=J16,"No Prazo","Atrasado")) -> No Prazo | N16: =IF(K16<>"",MAX(0,K16-J16),IF(TODAY()>J16,TODAY()-J16,0)) -> 0
A17: 100002001 | B17: =IFERROR(INDEX(Materiais!$B:$B,MATCH(A17,Materiais!$A:$A,0)),"") -> Mandibula Fixa do Britador | C17: 457015 | D17: 46237 | E17: F002 | F17: =IFERROR(INDEX(Fornecedores!$B:$B,MATCH(E17,Fornecedores!$A:$A,0)),"") -> Metso Outotec Brasil | G17: 10 | H17: =IFERROR(INDEX(Materiais!$F:$F,MATCH(A17,Materiais!$A:$A,0)),0) -> 18500 | I17: =G17*H17 -> 185000 | J17: 46267 | L17: =IF(K17<>"","Recebido",IF(TODAY()>J17,"Atrasado","Em Transito")) -> Em Transito | M17: =IF(K17="","-",IF(K17<=J17,"No Prazo","Atrasado")) -> - | N17: =IF(K17<>"",MAX(0,K17-J17),IF(TODAY()>J17,TODAY()-J17,0)) -> 0
A18: 100002004 | B18: =IFERROR(INDEX(Materiais!$B:$B,MATCH(A18,Materiais!$A:$A,0)),"") -> Revestimento Manto | C18: 457016 | D18: 46172 | E18: F002 | F18: =IFERROR(INDEX(Fornecedores!$B:$B,MATCH(E18,Fornecedores!$A:$A,0)),"") -> Metso Outotec Brasil | G18: 6 | H18: =IFERROR(INDEX(Materiais!$F:$F,MATCH(A18,Materiais!$A:$A,0)),0) -> 11800 | I18: =G18*H18 -> 70800 | J18: 46202 | L18: =IF(K18<>"","Recebido",IF(TODAY()>J18,"Atrasado","Em Transito")) -> Atrasado | M18: =IF(K18="","-",IF(K18<=J18,"No Prazo","Atrasado")) -> - | N18: =IF(K18<>"",MAX(0,K18-J18),IF(TODAY()>J18,TODAY()-J18,0)) -> 55
A19: 100002007 | B19: =IFERROR(INDEX(Materiais!$B:$B,MATCH(A19,Materiais!$A:$A,0)),"") -> Placa de Impacto | C19: 457017 | D19: 46145 | E19: F003 | F19: =IFERROR(INDEX(Fornecedores!$B:$B,MATCH(E19,Fornecedores!$A:$A,0)),"") -> Sandvik Mining Brasil | G19: 8 | H19: =IFERROR(INDEX(Materiais!$F:$F,MATCH(A19,Materiais!$A:$A,0)),0) -> 1980 | I19: =G19*H19 -> 15840 | J19: 46170 | K19: 46182 | L19: =IF(K19<>"","Recebido",IF(TODAY()>J19,"Atrasado","Em Transito")) -> Recebido | M19: =IF(K19="","-",IF(K19<=J19,"No Prazo","Atrasado")) -> Atrasado | N19: =IF(K19<>"",MAX(0,K19-J19),IF(TODAY()>J19,TODAY()-J19,0)) -> 12
A20: 100002010 | B20: =IFERROR(INDEX(Materiais!$B:$B,MATCH(A20,Materiais!$A:$A,0)),"") -> Bucha Excentrica | C20: 457018 | D20: 46211 | E20: F007 | F20: =IFERROR(INDEX(Fornecedores!$B:$B,MATCH(E20,Fornecedores!$A:$A,0)),"") -> Rolamentos ABC Ltda | G20: 1 | H20: =IFERROR(INDEX(Materiais!$F:$F,MATCH(A20,Materiais!$A:$A,0)),0) -> 2150 | I20: =G20*H20 -> 2150 | J20: 46219 | K20: 46222 | L20: =IF(K20<>"","Recebido",IF(TODAY()>J20,"Atrasado","Em Transito")) -> Recebido | M20: =IF(K20="","-",IF(K20<=J20,"No Prazo","Atrasado")) -> Atrasado | N20: =IF(K20<>"",MAX(0,K20-J20),IF(TODAY()>J20,TODAY()-J20,0)) -> 3
A21: 100002356 | B21: =IFERROR(INDEX(Materiais!$B:$B,MATCH(A21,Materiais!$A:$A,0)),"") -> Rolamento 6205 | C21: 457019 | D21: 46169 | E21: F007 | F21: =IFERROR(INDEX(Fornecedores!$B:$B,MATCH(E21,Fornecedores!$A:$A,0)),"") -> Rolamentos ABC Ltda | G21: 8 | H21: =IFERROR(INDEX(Materiais!$F:$F,MATCH(A21,Materiais!$A:$A,0)),0) -> 145 | I21: =G21*H21 -> 1160 | J21: 46177 | K21: 46189 | L21: =IF(K21<>"","Recebido",IF(TODAY()>J21,"Atrasado","Em Transito")) -> Recebido | M21: =IF(K21="","-",IF(K21<=J21,"No Prazo","Atrasado")) -> Atrasado | N21: =IF(K21<>"",MAX(0,K21-J21),IF(TODAY()>J21,TODAY()-J21,0)) -> 12
A22: 100002359 | B22: =IFERROR(INDEX(Materiais!$B:$B,MATCH(A22,Materiais!$A:$A,0)),"") -> Rolamento Esferico 22318 | C22: 457020 | D22: 46176 | E22: F001 | F22: =IFERROR(INDEX(Fornecedores!$B:$B,MATCH(E22,Fornecedores!$A:$A,0)),"") -> SKF do Brasil Ltda | G22: 5 | H22: =IFERROR(INDEX(Materiais!$F:$F,MATCH(A22,Materiais!$A:$A,0)),0) -> 1240 | I22: =G22*H22 -> 6200 | J22: 46191 | K22: 46194 | L22: =IF(K22<>"","Recebido",IF(TODAY()>J22,"Atrasado","Em Transito")) -> Recebido | M22: =IF(K22="","-",IF(K22<=J22,"No Prazo","Atrasado")) -> Atrasado | N22: =IF(K22<>"",MAX(0,K22-J22),IF(TODAY()>J22,TODAY()-J22,0)) -> 3
A23: 100003001 | B23: =IFERROR(INDEX(Materiais!$B:$B,MATCH(A23,Materiais!$A:$A,0)),"") -> Correia Transportadora B-1200 | C23: 457021 | D23: 46201 | E23: F005 | F23: =IFERROR(INDEX(Fornecedores!$B:$B,MATCH(E23,Fornecedores!$A:$A,0)),"") -> Gates Correias Industriais | G23: 6 | H23: =IFERROR(INDEX(Materiais!$F:$F,MATCH(A23,Materiais!$A:$A,0)),0) -> 320 | I23: =G23*H23 -> 1920 | J23: 46211 | K23: 46223 | L23: =IF(K23<>"","Recebido",IF(TODAY()>J23,"Atrasado","Em Transito")) -> Recebido | M23: =IF(K23="","-",IF(K23<=J23,"No Prazo","Atrasado")) -> Atrasado | N23: =IF(K23<>"",MAX(0,K23-J23),IF(TODAY()>J23,TODAY()-J23,0)) -> 12
A24: 100003004 | B24: =IFERROR(INDEX(Materiais!$B:$B,MATCH(A24,Materiais!$A:$A,0)),"") -> Polia Movida | C24: 457022 | D24: 46147 | E24: F004 | F24: =IFERROR(INDEX(Fornecedores!$B:$B,MATCH(E24,Fornecedores!$A:$A,0)),"") -> WEG Equipamentos S.A. | G24: 10 | H24: =IFERROR(INDEX(Materiais!$F:$F,MATCH(A24,Materiais!$A:$A,0)),0) -> 2180 | I24: =G24*H24 -> 21800 | J24: 46159 | L24: =IF(K24<>"","Recebido",IF(TODAY()>J24,"Atrasado","Em Transito")) -> Atrasado | M24: =IF(K24="","-",IF(K24<=J24,"No Prazo","Atrasado")) -> - | N24: =IF(K24<>"",MAX(0,K24-J24),IF(TODAY()>J24,TODAY()-J24,0)) -> 98
A25: 100005001 | B25: =IFERROR(INDEX(Materiais!$B:$B,MATCH(A25,Materiais!$A:$A,0)),"") -> Motor Eletrico 150cv | C25: 457023 | D25: 46172 | E25: F004 | F25: =IFERROR(INDEX(Fornecedores!$B:$B,MATCH(E25,Fornecedores!$A:$A,0)),"") -> WEG Equipamentos S.A. | G25: 4 | H25: =IFERROR(INDEX(Materiais!$F:$F,MATCH(A25,Materiais!$A:$A,0)),0) -> 32500 | I25: =G25*H25 -> 130000 | J25: 46184 | L25: =IF(K25<>"","Recebido",IF(TODAY()>J25,"Atrasado","Em Transito")) -> Atrasado | M25: =IF(K25="","-",IF(K25<=J25,"No Prazo","Atrasado")) -> - | N25: =IF(K25<>"",MAX(0,K25-J25),IF(TODAY()>J25,TODAY()-J25,0)) -> 73
A26: 100005004 | B26: =IFERROR(INDEX(Materiais!$B:$B,MATCH(A26,Materiais!$A:$A,0)),"") -> Sensor de Vibracao | C26: 457024 | D26: 46122 | E26: F004 | F26: =IFERROR(INDEX(Fornecedores!$B:$B,MATCH(E26,Fornecedores!$A:$A,0)),"") -> WEG Equipamentos S.A. | G26: 10 | H26: =IFERROR(INDEX(Materiais!$F:$F,MATCH(A26,Materiais!$A:$A,0)),0) -> 1350 | I26: =G26*H26 -> 13500 | J26: 46134 | L26: =IF(K26<>"","Recebido",IF(TODAY()>J26,"Atrasado","Em Transito")) -> Atrasado | M26: =IF(K26="","-",IF(K26<=J26,"No Prazo","Atrasado")) -> - | N26: =IF(K26<>"",MAX(0,K26-J26),IF(TODAY()>J26,TODAY()-J26,0)) -> 123
A27: 100005007 | B27: =IFERROR(INDEX(Materiais!$B:$B,MATCH(A27,Materiais!$A:$A,0)),"") -> Contator Tripolar | C27: 457025 | D27: 46121 | E27: F004 | F27: =IFERROR(INDEX(Fornecedores!$B:$B,MATCH(E27,Fornecedores!$A:$A,0)),"") -> WEG Equipamentos S.A. | G27: 10 | H27: =IFERROR(INDEX(Materiais!$F:$F,MATCH(A27,Materiais!$A:$A,0)),0) -> 340 | I27: =G27*H27 -> 3400 | J27: 46133 | K27: 46145 | L27: =IF(K27<>"","Recebido",IF(TODAY()>J27,"Atrasado","Em Transito")) -> Recebido | M27: =IF(K27="","-",IF(K27<=J27,"No Prazo","Atrasado")) -> Atrasado | N27: =IF(K27<>"",MAX(0,K27-J27),IF(TODAY()>J27,TODAY()-J27,0)) -> 12
A28: 100006003 | B28: =IFERROR(INDEX(Materiais!$B:$B,MATCH(A28,Materiais!$A:$A,0)),"") -> Mangueira Hidraulica 1 polegada | C28: 457026 | D28: 46199 | E28: F006 | F28: =IFERROR(INDEX(Fornecedores!$B:$B,MATCH(E28,Fornecedores!$A:$A,0)),"") -> Bosch Rexroth Brasil | G28: 3 | H28: =IFERROR(INDEX(Materiais!$F:$F,MATCH(A28,Materiais!$A:$A,0)),0) -> 85 | I28: =G28*H28 -> 255 | J28: 46219 | K28: 46219 | L28: =IF(K28<>"","Recebido",IF(TODAY()>J28,"Atrasado","Em Transito")) -> Recebido | M28: =IF(K28="","-",IF(K28<=J28,"No Prazo","Atrasado")) -> No Prazo | N28: =IF(K28<>"",MAX(0,K28-J28),IF(TODAY()>J28,TODAY()-J28,0)) -> 0
A29: 100007002 | B29: =IFERROR(INDEX(Materiais!$B:$B,MATCH(A29,Materiais!$A:$A,0)),"") -> Filtro de Oleo Lubrificante | C29: 457027 | D29: 46140 | E29: F007 | F29: =IFERROR(INDEX(Fornecedores!$B:$B,MATCH(E29,Fornecedores!$A:$A,0)),"") -> Rolamentos ABC Ltda | G29: 3 | H29: =IFERROR(INDEX(Materiais!$F:$F,MATCH(A29,Materiais!$A:$A,0)),0) -> 95 | I29: =G29*H29 -> 285 | J29: 46148 | L29: =IF(K29<>"","Recebido",IF(TODAY()>J29,"Atrasado","Em Transito")) -> Atrasado | M29: =IF(K29="","-",IF(K29<=J29,"No Prazo","Atrasado")) -> - | N29: =IF(K29<>"",MAX(0,K29-J29),IF(TODAY()>J29,TODAY()-J29,0)) -> 109
A30: 100008002 | B30: =IFERROR(INDEX(Materiais!$B:$B,MATCH(A30,Materiais!$A:$A,0)),"") -> Graxa Industrial EP2 | C30: 457028 | D30: 46129 | E30: F008 | F30: =IFERROR(INDEX(Fornecedores!$B:$B,MATCH(E30,Fornecedores!$A:$A,0)),"") -> Ferragens Industrial XYZ | G30: 9 | H30: =IFERROR(INDEX(Materiais!$F:$F,MATCH(A30,Materiais!$A:$A,0)),0) -> 32 | I30: =G30*H30 -> 288 | J30: 46134 | K30: 46141 | L30: =IF(K30<>"","Recebido",IF(TODAY()>J30,"Atrasado","Em Transito")) -> Recebido | M30: =IF(K30="","-",IF(K30<=J30,"No Prazo","Atrasado")) -> Atrasado | N30: =IF(K30<>"",MAX(0,K30-J30),IF(TODAY()>J30,TODAY()-J30,0)) -> 7
A31: 100009003 | B31: =IFERROR(INDEX(Materiais!$B:$B,MATCH(A31,Materiais!$A:$A,0)),"") -> Arruela de Pressao M24 | C31: 457029 | D31: 46121 | E31: F008 | F31: =IFERROR(INDEX(Fornecedores!$B:$B,MATCH(E31,Fornecedores!$A:$A,0)),"") -> Ferragens Industrial XYZ | G31: 6 | H31: =IFERROR(INDEX(Materiais!$F:$F,MATCH(A31,Materiais!$A:$A,0)),0) -> 2.2 | I31: =G31*H31 -> 13.2 | J31: 46126 | L31: =IF(K31<>"","Recebido",IF(TODAY()>J31,"Atrasado","Em Transito")) -> Atrasado | M31: =IF(K31="","-",IF(K31<=J31,"No Prazo","Atrasado")) -> - | N31: =IF(K31<>"",MAX(0,K31-J31),IF(TODAY()>J31,TODAY()-J31,0)) -> 131
A32: 100008002 | B32: =IFERROR(INDEX(Materiais!$B:$B,MATCH(A32,Materiais!$A:$A,0)),"") -> Graxa Industrial EP2 | C32: 457029 | D32: 46129 | E32: F008 | F32: =IFERROR(INDEX(Fornecedores!$B:$B,MATCH(E32,Fornecedores!$A:$A,0)),"") -> Ferragens Industrial XYZ | G32: 9 | H32: =IFERROR(INDEX(Materiais!$F:$F,MATCH(A32,Materiais!$A:$A,0)),0) -> 32 | I32: =G32*H32 -> 288 | J32: 46134 | K32: 46141 | L32: =IF(K32<>"","Recebido",IF(TODAY()>J32,"Atrasado","Em Transito")) -> Recebido | M32: =IF(K32="","-",IF(K32<=J32,"No Prazo","Atrasado")) -> Atrasado | N32: =IF(K32<>"",MAX(0,K32-J32),IF(TODAY()>J32,TODAY()-J32,0)) -> 7
A33: 100008002 | B33: =IFERROR(INDEX(Materiais!$B:$B,MATCH(A33,Materiais!$A:$A,0)),"") -> Graxa Industrial EP2 | C33: 457029 | D33: 46129 | E33: F008 | F33: =IFERROR(INDEX(Fornecedores!$B:$B,MATCH(E33,Fornecedores!$A:$A,0)),"") -> Ferragens Industrial XYZ | G33: 9 | H33: =IFERROR(INDEX(Materiais!$F:$F,MATCH(A33,Materiais!$A:$A,0)),0) -> 32 | I33: =G33*H33 -> 288 | J33: 46134 | K33: 46141 | L33: =IF(K33<>"","Recebido",IF(TODAY()>J33,"Atrasado","Em Transito")) -> Recebido | M33: =IF(K33="","-",IF(K33<=J33,"No Prazo","Atrasado")) -> Atrasado | N33: =IF(K33<>"",MAX(0,K33-J33),IF(TODAY()>J33,TODAY()-J33,0)) -> 7

Sheet Indicadores
A1: 1. VALOR EM ESTOQUE POR CATEGORIA
A2: Categoria | B2: Valor (R$)
A3: Correias e Polias | B3: =SUMIF(Materiais!$C:$C,A3,Materiais!$P:$P) -> 7665
A4: Eletrico | B4: =SUMIF(Materiais!$C:$C,A4,Materiais!$P:$P) -> 144040
A5: Estrutural | B5: =SUMIF(Materiais!$C:$C,A5,Materiais!$P:$P) -> 82450
A6: Filtros | B6: =SUMIF(Materiais!$C:$C,A6,Materiais!$P:$P) -> 9990
A7: Fixacao | B7: =SUMIF(Materiais!$C:$C,A7,Materiais!$P:$P) -> 12102.5
A8: Hidraulico | B8: =SUMIF(Materiais!$C:$C,A8,Materiais!$P:$P) -> 73400
A9: Lubrificacao | B9: =SUMIF(Materiais!$C:$C,A9,Materiais!$P:$P) -> 7600
A10: Molas e Amortecedores | B10: =SUMIF(Materiais!$C:$C,A10,Materiais!$P:$P) -> 29200
A11: Revestimentos | B11: =SUMIF(Materiais!$C:$C,A11,Materiais!$P:$P) -> 145360
A12: Rolamentos | B12: =SUMIF(Materiais!$C:$C,A12,Materiais!$P:$P) -> 46628
A15: 2. STATUS DAS REQUISICOES (RC) | I15: Rótulos de Linha | J15: Contagem de Numero RC
A16: Status | B16: Quantidade | I16: Aguardando Aprovacao | J16: 2
A17: Pendente | B17: =GETPIVOTDATA("Numero RC",$I$15,"Status","Pendente") -> 8 | I17: Convertida | J17: 13
A18: Aguardando Aprovacao | B18: =GETPIVOTDATA("Numero RC",$I$15,"Status","Aguardando Aprovacao") -> 2 | I18: Em Cotacao | J18: 7
A19: Em Cotacao | B19: =GETPIVOTDATA("Numero RC",$I$15,"Status","Em Cotacao") -> 7 | I19: Pendente | J19: 8
A20: Convertida | B20: =GETPIVOTDATA("Numero RC",$I$15,"Status","Convertida") -> 13 | I20: Total Geral | J20: 30
A23: 3. STATUS DOS PEDIDOS (OC) | F23: Rótulos de Linha | G23: Contagem de Numero OC
A24: Status | B24: Quantidade | F24: Atrasado | G24: 13
A25: Em Transito | B25: =GETPIVOTDATA("Numero OC",$F$23,"Status","Em Transito") -> 1 | F25: Em Transito | G25: 1
A26: Atrasado | B26: =GETPIVOTDATA("Numero OC",$F$23,"Status","Atrasado") -> 13 | F26: Recebido | G26: 16
A27: Recebido | B27: =GETPIVOTDATA("Numero OC",$F$23,"Status","Recebido") -> 16 | F27: Total Geral | G27: 30
A30: 4. COBERTURA DE ESTOQUE (FAIXAS)
A31: Faixa | B31: Qtde Materiais
A32: Menos de 7 dias | B32: =COUNTIF(Materiais!$Q:$Q,"<7") -> 45
A33: De 7 a 30 dias | B33: =COUNTIFS(Materiais!$Q:$Q,">=7",Materiais!$Q:$Q,"<30") -> 0
A34: De 30 a 90 dias | B34: =COUNTIFS(Materiais!$Q:$Q,">=30",Materiais!$Q:$Q,"<90") -> 0
A35: Mais de 90 dias | B35: =COUNTIF(Materiais!$Q:$Q,">=90") -> 0
A38: 5. CURVA ABC
A39: Classe | B39: Qtde Materiais | C39: Valor (R$)
A40: A | B40: =COUNTIF(Materiais!$X:$X,A40) -> 11 | C40: =SUMIF(Materiais!$X:$X,A40,Materiais!$P:$P) -> 390710
A41: B | B41: =COUNTIF(Materiais!$X:$X,A41) -> 8 | C41: =SUMIF(Materiais!$X:$X,A41,Materiais!$P:$P) -> 111080
A42: C | B42: =COUNTIF(Materiais!$X:$X,A42) -> 26 | C42: =SUMIF(Materiais!$X:$X,A42,Materiais!$P:$P) -> 56645.5
A45: 6. ESTOQUE PARADO POR FAIXA DE DIAS
A46: Faixa | B46: Valor Parado (R$)
A47: 90 a 180 dias | B47: =SUMIFS(Materiais!$P:$P,Materiais!$T:$T,">=90",Materiais!$T:$T,"<180") -> 0
A48: 180 a 365 dias | B48: =SUMIFS(Materiais!$P:$P,Materiais!$T:$T,">=180",Materiais!$T:$T,"<365") -> 0
A49: Mais de 365 dias | B49: =SUMIFS(Materiais!$P:$P,Materiais!$T:$T,">=365") -> 558435.5
A52: 7. PEDIDOS ATRASADOS POR FORNECEDOR
...
