Workbook

Sheet Leia-me
A1: GESTAO DE PECAS DO BRITADOR — GUIA RAPIDO DA PLANILHA
A3: ABA | B3: O QUE FAZ
A4: Dashboard | B4: Visao executiva: cards de indicadores e 6 graficos (valor por categoria, status de RCs, status de pedidos, cobertura de estoque, curva ABC e estoque parado). Tudo calculado por formula.
A5: Materiais | B5: Cadastro mestre das pecas do britador (45 itens de exemplo). Colunas de entrada em preto (codigo, nome, custo, saldo, min/max, localizacao, criticidade) e colunas calculadas (cobertura, giro, status, risco de ruptura, curva ABC).
A6: Fornecedores | B6: Cadastro dos fornecedores com lead time e indicadores de performance (OTIF, atrasos), calculados a partir da aba Pedidos.
A7: Movimentacoes | B7: Historico de entradas e saidas de estoque (6 meses de exemplo). Alimenta o consumo medio e o giro de estoque em Materiais.
A8: Requisicoes | B8: Controle de RCs (requisicoes de compra) com status (Pendente, Aguardando Aprovacao, Em Cotacao, Convertida).
A9: Pedidos | B9: Controle de OCs (pedidos de compra) com datas previstas/recebidas, status e atraso calculados automaticamente.
A10: Indicadores | B10: Aba de apoio: agrega os dados das demais abas nas tabelas que alimentam os graficos do Dashboard. Nao precisa editar.
A12: COMO ATUALIZAR OS DADOS
A13: 1. | B13: Adicione novas pecas na aba Materiais (proxima linha livre), preenchendo as colunas A ate K. As colunas L em diante sao formulas — copie-as da ultima linha para baixo.
A14: 2. | B14: Registre entradas e saidas de estoque na aba Movimentacoes.
A15: 3. | B15: Registre novas requisicoes e pedidos nas abas Requisicoes e Pedidos.
A16: 4. | B16: O Dashboard e a aba Indicadores recalculam automaticamente — nao exigem nenhuma acao manual.
A18: OBSERVACAO | B18: Os dados de materiais, fornecedores, movimentacoes, requisicoes e pedidos sao EXEMPLOS para demonstrar a estrutura e os indicadores. Substitua pelos dados reais da mineradora.

Sheet Dashboard
B1: DASHBOARD EXECUTIVO — GESTAO DE MATERIAIS
L2: CRITICO REFAZER | N2: CONFERIR ABAS MATERIAIS
B3: VALOR EM ESTOQUE | D3: ESTOQUE PARADO (R$) | G3: PEDIDOS ATRASADOS | I3: PEDIDOS EM ABERTO | L3: MATERIAIS CRITICOS | N3: RISCO DE RUPTURA (ALTO)
B4: =SUM(Materiais!$O:$O) -> 20254417 | D4: =SUMIF(Materiais!$S:$S,">=90",Materiais!$O:$O) -> 11953600 | G4: =COUNTIF(Pedidos!$L:$L,"Atrasado") -> 36 | I4: =COUNTIF(Pedidos!L2:L137,"<>Recebido") -> 46 | K4: COBERTURA | L4: =COUNTIF(Materiais!J2:J46,"Critico") -> 17 | N4: =COUNTIF(Materiais!$U:$U,"Alto") -> 3
B6: TOTAL DE MATERIAIS | D6: % OTIF MEDIO | G6: COMPRAS EM ABERTO | I6: RC's PENDENTES | L6: LEAD TIME MEDIO | N6: GIRO DE ESTOQUE
B7: =COUNTA(Materiais!$A:$A)-1 -> 45 | D7: =ROUND(AVERAGE(Fornecedores!$H:$H),3) -> 0.856 | G7: =SUMIF(Pedidos!$L:$L,"<>Recebido",Pedidos!$I:$I) -> 13250820 | I7: =Indicadores!B17 -> 8 | L7: =ROUND(AVERAGE(Fornecedores!$D:$D),0)&" dias" -> 7 dias | N7: =ROUND(AVERAGE(Materiais!S2:S46),1)&"x/ano" -> 22x/ano
B46: Fonte: abas Materiais, Fornecedores, Movimentacoes, Requisicoes e Pedidos. Indicadores calculados por formula (SUMIFS/COUNTIFS/INDEX-MATCH) na aba Indicadores. Dados de exemplo — substitua pelos dados reais da mineradora.

Sheet Materiais
A1: Cod | B1: Material | C1: Categoria | D1: Unidade | E1: Custo Unitario (R$) | F1: Saldo Atual | G1: Estoque Minimo | H1: Estoque Maximo | I1: Localizacao | J1: Criticidade | K1: Lead Time (dias) | L1: Consumo Medio Diário | M1: Ponto de Reposicao | N1: Lote Reposição | O1: Valor em Estoque (R$) | P1: Cobertura (dias) | Q1: Ultima Movimentacao | R1: Giro Anual | S1: Dias sem Movimentacao | T1: Status Estoque | U1: Risco de Ruptura | V1: Valor Acumulado % | W1: Classe ABC | X1: MATRIZ ABC XYZ
A2: 2359 | B2: Rolamento Esferico 22318 | C2: Rolamentos | D2: UN | E2: 1240 | F2: =SUMIFS(Movimentacoes!$H:$H, Movimentacoes!$D:$D, A2) -> 51 | G2: =IFERROR(L4*(K4*1.1),"") -> 7.92 | H2: =IFERROR((G4+L4)*K4,"") -> 111.92 | I2: A-05-05 | J2: Critico | K2: =AVERAGEIFS(Pedidos!$O:$O,Pedidos!$A:$A,A2,Pedidos!$L:$L,"Recebido") -> 7 | L2: =ABS(SUMIFS(Movimentacoes!$H:$H,Movimentacoes!$D:$D,A2,Movimentacoes!$C:$C,261))/MAX(1,_xlfn.MAXIFS(Movimentacoes!$A:$A,Movimentacoes!$D:$D,A2)-_xlfn.MINIFS(Movimentacoes!$A:$A,Movimentacoes!$D:$D,A2)+1) -> 1.4824561 | M2: =IFERROR(G4+(L4*K4),"") -> 20.29 | N2: =IFERROR(H4-G4,"") -> 31.15 | O2: =F2*E2 -> 63240 | P2: =IFERROR(ROUND(F2/L2,1),0) -> 34.4 | Q2: =IFERROR(_xlfn.MAXIFS(Movimentacoes!$A:$A,Movimentacoes!$D:$D,A2),"") -> 46254 | R2: =ABS(SUMIFS(Movimentacoes!$H:$H, Movimentacoes!$D:$D, Materiais!A2, Movimentacoes!$C:$C, "261")) /(( (INDEX(Movimentacoes!$I:$I, MATCH(A2, Movimentacoes!$D:$D, 0)) - INDEX(Movimentacoes!$H:$H, MATCH(A2, Movimentacoes!$D:$D, 0))) + LOOKUP(2, 1/(Movimentacoes!$D:$D=A2), Movimentacoes!$I:$I) ) / 2) -> 13.254902 | S2: =IF(Q2="","",TODAY()-Q2) -> 5 | T2: =IF(F2<=0,"Ruptura",IF(F2<G2,"Abaixo do Minimo",IF(F2<M2,"Ponto de Reposicao","Normal"))) -> Normal | U2: =IF(AND(J2="Critico",P2<K2),"Alto",IF(P2<K2,"Medio","Baixo")) -> Baixo | V2: =SUMPRODUCT(($O$2:$O$46>=O2)*$O$2:$O$46)/SUM($O$2:$O$46) -> 0.98957576 | W2: =IF(V2<=0.7,"A",IF(V2<=0.9,"B","C")) -> C
A3: 2008 | B3: Eixo Excentrico | C3: Estrutural | D3: UN | E3: 24500 | F3: =SUMIFS(Movimentacoes!$H:$H, Movimentacoes!$D:$D, A3) -> 11 | G3: =IFERROR(L5*(K5*1.1),"") -> 8.8 | H3: =IFERROR((G5+L5)*K5,"") -> 81.92 | I3: A-01-03 | J3: Critico | K3: =AVERAGEIFS(Pedidos!$O:$O,Pedidos!$A:$A,A3,Pedidos!$L:$L,"Recebido") -> 8 | L3: =ROUND(ABS(SUMIFS(Movimentacoes!$H:$H,Movimentacoes!$D:$D,A3,Movimentacoes!$C:$C,"261"))/MAX(1,DATEDIF(_xlfn.MINIFS(Movimentacoes!$A:$A,Movimentacoes!$D:$D,A3,Movimentacoes!$C:$C,"261"),_xlfn.MAXIFS(Movimentacoes!$A:$A,Movimentacoes!$D:$D,A3,Movimentacoes!$C:$C,"261"),"d")),1) -> 1.6 | M3: =IFERROR(G5+(L5*K5),"") -> 17.24 | N3: =IFERROR(H5-G5,"") -> 54.215 | O3: =F3*E3 -> 269500 | P3: =IFERROR(ROUND(F3/L3,1),0) -> 6.9 | Q3: =IFERROR(_xlfn.MAXIFS(Movimentacoes!$A:$A,Movimentacoes!$D:$D,A3),"") -> 46249 | S3: =IF(Q3="","",TODAY()-Q3) -> 10 | T3: =IF(F3<=0,"Ruptura",IF(F3<G3,"Abaixo do Minimo",IF(F3<M3,"Ponto de Reposicao","Normal"))) -> Ponto de Reposicao | U3: =IF(AND(J3="Critico",P3<K3),"Alto",IF(P3<K3,"Medio","Baixo")) -> Alto | V3: =SUMPRODUCT(($O$2:$O$46>=O3)*$O$2:$O$46)/SUM($O$2:$O$46) -> 0.94148798 | W3: =IF(V3<=0.7,"A",IF(V3<=0.9,"B","C")) -> C
A4: 5004 | B4: Sensor de Vibracao | C4: Eletrico | D4: UN | E4: 1350 | F4: =SUMIFS(Movimentacoes!$H:$H, Movimentacoes!$D:$D, A4) -> 66 | G4: =IFERROR(L6*(K6*1.1),"") -> 13.09 | H4: =IFERROR((G6+L6)*K6,"") -> 44.24 | I4: C-01-04 | J4: Critico | K4: =AVERAGEIFS(Pedidos!$O:$O,Pedidos!$A:$A,A4,Pedidos!$L:$L,"Recebido") -> 8 | L4: =ROUND(ABS(SUMIFS(Movimentacoes!$H:$H,Movimentacoes!$D:$D,A4,Movimentacoes!$C:$C,"261"))/MAX(1,DATEDIF(_xlfn.MINIFS(Movimentacoes!$A:$A,Movimentacoes!$D:$D,A4,Movimentacoes!$C:$C,"261"),_xlfn.MAXIFS(Movimentacoes!$A:$A,Movimentacoes!$D:$D,A4,Movimentacoes!$C:$C,"261"),"d")),1) -> 0.9 | M4: =IFERROR(G6+(L6*K6),"") -> 16.52 | N4: =IFERROR(H6-G6,"") -> 37.31 | O4: =F4*E4 -> 89100 | P4: =IFERROR(ROUND(F4/L4,1),0) -> 73.3 | Q4: =IFERROR(_xlfn.MAXIFS(Movimentacoes!$A:$A,Movimentacoes!$D:$D,A4),"") -> 46256 | S4: =IF(Q4="","",TODAY()-Q4) -> 3 | T4: =IF(F4<=0,"Ruptura",IF(F4<G4,"Abaixo do Minimo",IF(F4<M4,"Ponto de Reposicao","Normal"))) -> Normal | U4: =IF(AND(J4="Critico",P4<K4),"Alto",IF(P4<K4,"Medio","Baixo")) -> Baixo | V4: =SUMPRODUCT(($O$2:$O$46>=O4)*$O$2:$O$46)/SUM($O$2:$O$46) -> 0.97534874 | W4: =IF(V4<=0.7,"A",IF(V4<=0.9,"B","C")) -> C
A5: 2009 | B5: Bucha de Bronze | C5: Estrutural | D5: UN | E5: 1650 | F5: =SUMIFS(Movimentacoes!$H:$H, Movimentacoes!$D:$D, A5) -> 99 | G5: =IFERROR(L7*(K7*1.1),"") -> 9.24 | H5: =IFERROR((G7+L7)*K7,"") -> 63.455 | I5: A-01-04 | J5: Critico | K5: =AVERAGEIFS(Pedidos!$O:$O,Pedidos!$A:$A,A5,Pedidos!$L:$L,"Recebido") -> 8 | L5: =ROUND(ABS(SUMIFS(Movimentacoes!$H:$H,Movimentacoes!$D:$D,A5,Movimentacoes!$C:$C,"261"))/MAX(1,DATEDIF(_xlfn.MINIFS(Movimentacoes!$A:$A,Movimentacoes!$D:$D,A5,Movimentacoes!$C:$C,"261"),_xlfn.MAXIFS(Movimentacoes!$A:$A,Movimentacoes!$D:$D,A5,Movimentacoes!$C:$C,"261"),"d")),1) -> 1 | M5: =IFERROR(G7+(L7*K7),"") -> 16.265 | N5: =IFERROR(H7-G7,"") -> 75.515 | O5: =F5*E5 -> 163350 | P5: =IFERROR(ROUND(F5/L5,1),0) -> 99 | Q5: =IFERROR(_xlfn.MAXIFS(Movimentacoes!$A:$A,Movimentacoes!$D:$D,A5),"") -> 46257 | S5: =IF(Q5="","",TODAY()-Q5) -> 2 | T5: =IF(F5<=0,"Ruptura",IF(F5<G5,"Abaixo do Minimo",IF(F5<M5,"Ponto de Reposicao","Normal"))) -> Normal | U5: =IF(AND(J5="Critico",P5<K5),"Alto",IF(P5<K5,"Medio","Baixo")) -> Baixo | V5: =SUMPRODUCT(($O$2:$O$46>=O5)*$O$2:$O$46)/SUM($O$2:$O$46) -> 0.94955288 | W5: =IF(V5<=0.7,"A",IF(V5<=0.9,"B","C")) -> C
A6: 3002 | B6: Correia em V A-75 | C6: Correias e Polias | D6: UN | E6: 95 | F6: =SUMIFS(Movimentacoes!$H:$H, Movimentacoes!$D:$D, A6) -> 8 | G6: =IFERROR(L8*(K8*1.1),"") -> 4.62 | H6: =IFERROR((G8+L8)*K8,"") -> 41.93 | I6: B-03-02 | J6: Nao Critico | K6: =AVERAGEIFS(Pedidos!$O:$O,Pedidos!$A:$A,A6,Pedidos!$L:$L,"Recebido") -> 7 | L6: =ROUND(ABS(SUMIFS(Movimentacoes!$H:$H,Movimentacoes!$D:$D,A6,Movimentacoes!$C:$C,"261"))/MAX(1,DATEDIF(_xlfn.MINIFS(Movimentacoes!$A:$A,Movimentacoes!$D:$D,A6,Movimentacoes!$C:$C,"261"),_xlfn.MAXIFS(Movimentacoes!$A:$A,Movimentacoes!$D:$D,A6,Movimentacoes!$C:$C,"261"),"d")),1) -> 1.7 | M6: =IFERROR(G8+(L8*K8),"") -> 9.59 | N6: =IFERROR(H8-G8,"") -> 45.71 | O6: =F6*E6 -> 760 | P6: =IFERROR(ROUND(F6/L6,1),0) -> 4.7 | Q6: =IFERROR(_xlfn.MAXIFS(Movimentacoes!$A:$A,Movimentacoes!$D:$D,A6),"") -> 46250 | S6: =IF(Q6="","",TODAY()-Q6) -> 9 | T6: =IF(F6<=0,"Ruptura",IF(F6<G6,"Abaixo do Minimo",IF(F6<M6,"Ponto de Reposicao","Normal"))) -> Ponto de Reposicao | U6: =IF(AND(J6="Critico",P6<K6),"Alto",IF(P6<K6,"Medio","Baixo")) -> Medio | V6: =SUMPRODUCT(($O$2:$O$46>=O6)*$O$2:$O$46)/SUM($O$2:$O$46) -> 0.99994039 | W6: =IF(V6<=0.7,"A",IF(V6<=0.9,"B","C")) -> C
A7: 2010 | B7: Bucha Excentrica | C7: Estrutural | D7: UN | E7: 2150 | F7: =SUMIFS(Movimentacoes!$H:$H, Movimentacoes!$D:$D, A7) -> 40 | G7: =IFERROR(L9*(K9*1.1),"") -> 7.865 | H7: =IFERROR((G9+L9)*K9,"") -> 83.38 | I7: A-01-05 | J7: Critico | K7: =AVERAGEIFS(Pedidos!$O:$O,Pedidos!$A:$A,A7,Pedidos!$L:$L,"Recebido") -> 7 | L7: =ROUND(ABS(SUMIFS(Movimentacoes!$H:$H,Movimentacoes!$D:$D,A7,Movimentacoes!$C:$C,"261"))/MAX(1,DATEDIF(_xlfn.MINIFS(Movimentacoes!$A:$A,Movimentacoes!$D:$D,A7,Movimentacoes!$C:$C,"261"),_xlfn.MAXIFS(Movimentacoes!$A:$A,Movimentacoes!$D:$D,A7,Movimentacoes!$C:$C,"261"),"d")),1) -> 1.2 | M7: =IFERROR(G9+(L9*K9),"") -> 21.01 | N7: =IFERROR(H9-G9,"") -> 70.735 | O7: =F7*E7 -> 86000 | P7: =IFERROR(ROUND(F7/L7,1),0) -> 33.3 | Q7: =IFERROR(_xlfn.MAXIFS(Movimentacoes!$A:$A,Movimentacoes!$D:$D,A7),"") -> 46257 | S7: =IF(Q7="","",TODAY()-Q7) -> 2 | T7: =IF(F7<=0,"Ruptura",IF(F7<G7,"Abaixo do Minimo",IF(F7<M7,"Ponto de Reposicao","Normal"))) -> Normal | U7: =IF(AND(J7="Critico",P7<K7),"Alto",IF(P7<K7,"Medio","Baixo")) -> Baixo | V7: =SUMPRODUCT(($O$2:$O$46>=O7)*$O$2:$O$46)/SUM($O$2:$O$46) -> 0.97959473 | W7: =IF(V7<=0.7,"A",IF(V7<=0.9,"B","C")) -> C
A8: 2001 | B8: Mandibula Fixa do Britador | C8: Estrutural | D8: UN | E8: 18500 | F8: =SUMIFS(Movimentacoes!$H:$H, Movimentacoes!$D:$D, A8) -> 224 | G8: =IFERROR(L10*(K10*1.1),"") -> 5.39 | H8: =IFERROR((G10+L10)*K10,"") -> 51.1 | I8: A-01-01 | J8: Critico | K8: =AVERAGEIFS(Pedidos!$O:$O,Pedidos!$A:$A,A8,Pedidos!$L:$L,"Recebido") -> 7 | L8: =ROUND(ABS(SUMIFS(Movimentacoes!$H:$H,Movimentacoes!$D:$D,A8,Movimentacoes!$C:$C,"261"))/MAX(1,DATEDIF(_xlfn.MINIFS(Movimentacoes!$A:$A,Movimentacoes!$D:$D,A8,Movimentacoes!$C:$C,"261"),_xlfn.MAXIFS(Movimentacoes!$A:$A,Movimentacoes!$D:$D,A8,Movimentacoes!$C:$C,"261"),"d")),1) -> 0.6 | M8: =IFERROR(G10+(L10*K10),"") -> 11.5 | N8: =IFERROR(H10-G10,"") -> 51.76 | O8: =F8*E8 -> 4144000 | P8: =IFERROR(ROUND(F8/L8,1),0) -> 373.3 | Q8: =IFERROR(_xlfn.MAXIFS(Movimentacoes!$A:$A,Movimentacoes!$D:$D,A8),"") -> 45892 | S8: =IF(Q8="","",TODAY()-Q8) -> 367 | T8: =IF(F8<=0,"Ruptura",IF(F8<G8,"Abaixo do Minimo",IF(F8<M8,"Ponto de Reposicao","Normal"))) -> Normal | U8: =IF(AND(J8="Critico",P8<K8),"Alto",IF(P8<K8,"Medio","Baixo")) -> Baixo | V8: =SUMPRODUCT(($O$2:$O$46>=O8)*$O$2:$O$46)/SUM($O$2:$O$46) -> 0.50568723 | W8: =IF(V8<=0.7,"A",IF(V8<=0.9,"B","C")) -> A
A9: 5002 | B9: Motor Eletrico 75cv | C9: Eletrico | D9: UN | E9: 17800 | F9: =SUMIFS(Movimentacoes!$H:$H, Movimentacoes!$D:$D, A9) -> 22 | G9: =IFERROR(L11*(K11*1.1),"") -> 13.86 | H9: =IFERROR((G11+L11)*K11,"") -> 84.595 | I9: C-01-02 | J9: Nao Critico | K9: =AVERAGEIFS(Pedidos!$O:$O,Pedidos!$A:$A,A9,Pedidos!$L:$L,"Recebido") -> 5.5 | L9: =ROUND(ABS(SUMIFS(Movimentacoes!$H:$H,Movimentacoes!$D:$D,A9,Movimentacoes!$C:$C,"261"))/MAX(1,DATEDIF(_xlfn.MINIFS(Movimentacoes!$A:$A,Movimentacoes!$D:$D,A9,Movimentacoes!$C:$C,"261"),_xlfn.MAXIFS(Movimentacoes!$A:$A,Movimentacoes!$D:$D,A9,Movimentacoes!$C:$C,"261"),"d")),1) -> 1.3 | M9: =IFERROR(G11+(L11*K11),"") -> 22.885 | N9: =IFERROR(H11-G11,"") -> 103.785 | O9: =F9*E9 -> 391600 | P9: =IFERROR(ROUND(F9/L9,1),0) -> 16.9 | Q9: =IFERROR(_xlfn.MAXIFS(Movimentacoes!$A:$A,Movimentacoes!$D:$D,A9),"") -> 46250 | S9: =IF(Q9="","",TODAY()-Q9) -> 9 | T9: =IF(F9<=0,"Ruptura",IF(F9<G9,"Abaixo do Minimo",IF(F9<M9,"Ponto de Reposicao","Normal"))) -> Ponto de Reposicao | U9: =IF(AND(J9="Critico",P9<K9),"Alto",IF(P9<K9,"Medio","Baixo")) -> Baixo | V9: =SUMPRODUCT(($O$2:$O$46>=O9)*$O$2:$O$46)/SUM($O$2:$O$46) -> 0.89417978 | W9: =IF(V9<=0.7,"A",IF(V9<=0.9,"B","C")) -> B
A10: 5005 | B10: Sensor de Temperatura | C10: Eletrico | D10: UN | E10: 780 | F10: =SUMIFS(Movimentacoes!$H:$H, Movimentacoes!$D:$D, A10) -> 141 | G10: =IFERROR(L12*(K12*1.1),"") -> 6.6 | H10: =IFERROR((G12+L12)*K12,"") -> 58.36 | I10: C-01-05 | J10: Nao Critico | K10: =AVERAGEIFS(Pedidos!$O:$O,Pedidos!$A:$A,A10,Pedidos!$L:$L,"Recebido") -> 7 | L10: =ROUND(ABS(SUMIFS(Movimentacoes!$H:$H,Movimentacoes!$D:$D,A10,Movimentacoes!$C:$C,"261"))/MAX(1,DATEDIF(_xlfn.MINIFS(Movimentacoes!$A:$A,Movimentacoes!$D:$D,A10,Movimentacoes!$C:$C,"261"),_xlfn.MAXIFS(Movimentacoes!$A:$A,Movimentacoes!$D:$D,A10,Movimentacoes!$C:$C,"261"),"d")),1) -> 0.7 | M10: =IFERROR(G12+(L12*K12),"") -> 19.09 | N10: =IFERROR(H12-G12,"") -> 97.37 | O10: =F10*E10 -> 109980 | P10: =IFERROR(ROUND(F10/L10,1),0) -> 201.4 | Q10: =IFERROR(_xlfn.MAXIFS(Movimentacoes!$A:$A,Movimentacoes!$D:$D,A10),"") -> 46257 | S10: =IF(Q10="","",TODAY()-Q10) -> 2 | T10: =IF(F10<=0,"Ruptura",IF(F10<G10,"Abaixo do Minimo",IF(F10<M10,"Ponto de Reposicao","Normal"))) -> Normal | U10: =IF(AND(J10="Critico",P10<K10),"Alto",IF(P10<K10,"Medio","Baixo")) -> Baixo | V10: =SUMPRODUCT(($O$2:$O$46>=O10)*$O$2:$O$46)/SUM($O$2:$O$46) -> 0.96618037 | W10: =IF(V10<=0.7,"A",IF(V10<=0.9,"B","C")) -> C
A11: 2357 | B11: Rolamento 6308 | C11: Rolamentos | D11: UN | E11: 210 | F11: =SUMIFS(Movimentacoes!$H:$H, Movimentacoes!$D:$D, A11) -> 71 | G11: =IFERROR(L13*(K13*1.1),"") -> 10.285 | H11: =IFERROR((G13+L13)*K13,"") -> 114.07 | I11: A-05-03 | J11: Nao Critico | K11: =AVERAGEIFS(Pedidos!$O:$O,Pedidos!$A:$A,A11,Pedidos!$L:$L,"Recebido") -> 7 | L11: =ROUND(ABS(SUMIFS(Movimentacoes!$H:$H,Movimentacoes!$D:$D,A11,Movimentacoes!$C:$C,"261"))/MAX(1,DATEDIF(_xlfn.MINIFS(Movimentacoes!$A:$A,Movimentacoes!$D:$D,A11,Movimentacoes!$C:$C,"261"),_xlfn.MAXIFS(Movimentacoes!$A:$A,Movimentacoes!$D:$D,A11,Movimentacoes!$C:$C,"261"),"d")),1) -> 1.8 | M11: =IFERROR(G13+(L13*K13),"") -> 21.67 | N11: =IFERROR(H13-G13,"") -> 85.12 | O11: =F11*E11 -> 14910 | P11: =IFERROR(ROUND(F11/L11,1),0) -> 39.4 | Q11: =IFERROR(_xlfn.MAXIFS(Movimentacoes!$A:$A,Movimentacoes!$D:$D,A11),"") -> 46253 | S11: =IF(Q11="","",TODAY()-Q11) -> 6 | T11: =IF(F11<=0,"Ruptura",IF(F11<G11,"Abaixo do Minimo",IF(F11<M11,"Ponto de Reposicao","Normal"))) -> Normal | U11: =IF(AND(J11="Critico",P11<K11),"Alto",IF(P11<K11,"Medio","Baixo")) -> Baixo | V11: =SUMPRODUCT(($O$2:$O$46>=O11)*$O$2:$O$46)/SUM($O$2:$O$46) -> 0.99650264 | W11: =IF(V11<=0.7,"A",IF(V11<=0.9,"B","C")) -> C
A12: 9005 | B12: Anel de Vedacao O-ring | C12: Fixacao | D12: UN | E12: 8.9 | F12: =SUMIFS(Movimentacoes!$H:$H, Movimentacoes!$D:$D, A12) -> 64 | G12: =IFERROR(L14*(K14*1.1),"") -> 13.09 | H12: =IFERROR((G14+L14)*K14,"") -> 110.46 | I12: D-02-05 | J12: Nao Critico | K12: =AVERAGEIFS(Pedidos!$O:$O,Pedidos!$A:$A,A12,Pedidos!$L:$L,"Recebido") -> 4 | L12: =ROUND(ABS(SUMIFS(Movimentacoes!$H:$H,Movimentacoes!$D:$D,A12,Movimentacoes!$C:$C,"261"))/MAX(1,DATEDIF(_xlfn.MINIFS(Movimentacoes!$A:$A,Movimentacoes!$D:$D,A12,Movimentacoes!$C:$C,"261"),_xlfn.MAXIFS(Movimentacoes!$A:$A,Movimentacoes!$D:$D,A12,Movimentacoes!$C:$C,"261"),"d")),1) -> 1.5 | M12: =IFERROR(G14+(L14*K14),"") -> 25.98 | N12: =IFERROR(H14-G14,"") -> 97.28 | O12: =F12*E12 -> 569.6 | P12: =IFERROR(ROUND(F12/L12,1),0) -> 42.7 | Q12: =IFERROR(_xlfn.MAXIFS(Movimentacoes!$A:$A,Movimentacoes!$D:$D,A12),"") -> 46253 | S12: =IF(Q12="","",TODAY()-Q12) -> 6 | T12: =IF(F12<=0,"Ruptura",IF(F12<G12,"Abaixo do Minimo",IF(F12<M12,"Ponto de Reposicao","Normal"))) -> Normal | U12: =IF(AND(J12="Critico",P12<K12),"Alto",IF(P12<K12,"Medio","Baixo")) -> Baixo | V12: =SUMPRODUCT(($O$2:$O$46>=O12)*$O$2:$O$46)/SUM($O$2:$O$46) -> 0.99996851 | W12: =IF(V12<=0.7,"A",IF(V12<=0.9,"B","C")) -> C
A13: 6003 | B13: Mangueira Hidraulica 1 polegada | C13: Hidraulico | D13: M | E13: 85 | F13: =SUMIFS(Movimentacoes!$H:$H, Movimentacoes!$D:$D, A13) -> 10 | G13: =IFERROR(L15*(K15*1.1),"") -> 12.32 | H13: =IFERROR((G15+L15)*K15,"") -> 97.44 | I13: C-02-03 | J13: Nao Critico | K13: =AVERAGEIFS(Pedidos!$O:$O,Pedidos!$A:$A,A13,Pedidos!$L:$L,"Recebido") -> 8.5 | L13: =ROUND(ABS(SUMIFS(Movimentacoes!$H:$H,Movimentacoes!$D:$D,A13,Movimentacoes!$C:$C,"261"))/MAX(1,DATEDIF(_xlfn.MINIFS(Movimentacoes!$A:$A,Movimentacoes!$D:$D,A13,Movimentacoes!$C:$C,"261"),_xlfn.MAXIFS(Movimentacoes!$A:$A,Movimentacoes!$D:$D,A13,Movimentacoes!$C:$C,"261"),"d")),1) -> 1.1 | M13: =IFERROR(G15+(L15*K15),"") -> 23.52 | N13: =IFERROR(H15-G15,"") -> 85.12 | O13: =F13*E13 -> 850 | P13: =IFERROR(ROUND(F13/L13,1),0) -> 9.1 | Q13: =IFERROR(_xlfn.MAXIFS(Movimentacoes!$A:$A,Movimentacoes!$D:$D,A13),"") -> 46250 | S13: =IF(Q13="","",TODAY()-Q13) -> 9 | T13: =IF(F13<=0,"Ruptura",IF(F13<G13,"Abaixo do Minimo",IF(F13<M13,"Ponto de Reposicao","Normal"))) -> Abaixo do Minimo | U13: =IF(AND(J13="Critico",P13<K13),"Alto",IF(P13<K13,"Medio","Baixo")) -> Baixo | V13: =SUMPRODUCT(($O$2:$O$46>=O13)*$O$2:$O$46)/SUM($O$2:$O$46) -> 0.9998236 | W13: =IF(V13<=0.7,"A",IF(V13<=0.9,"B","C")) -> C
A14: 6001 | B14: Cilindro Hidraulico de Ajuste | C14: Hidraulico | D14: UN | E14: 15800 | F14: =SUMIFS(Movimentacoes!$H:$H, Movimentacoes!$D:$D, A14) -> 39 | G14: =IFERROR(L16*(K16*1.1),"") -> 14.08 | H14: =IFERROR((G16+L16)*K16,"") -> 111.36 | I14: C-02-01 | J14: Critico | K14: =AVERAGEIFS(Pedidos!$O:$O,Pedidos!$A:$A,A14,Pedidos!$L:$L,"Recebido") -> 7 | L14: =ROUND(ABS(SUMIFS(Movimentacoes!$H:$H,Movimentacoes!$D:$D,A14,Movimentacoes!$C:$C,"261"))/MAX(1,DATEDIF(_xlfn.MINIFS(Movimentacoes!$A:$A,Movimentacoes!$D:$D,A14,Movimentacoes!$C:$C,"261"),_xlfn.MAXIFS(Movimentacoes!$A:$A,Movimentacoes!$D:$D,A14,Movimentacoes!$C:$C,"261"),"d")),1) -> 1.7 | M14: =IFERROR(G16+(L16*K16),"") -> 25.12 | N14: =IFERROR(H16-G16,"") -> 74.34 | O14: =F14*E14 -> 616200 | P14: =IFERROR(ROUND(F14/L14,1),0) -> 22.9 | Q14: =IFERROR(_xlfn.MAXIFS(Movimentacoes!$A:$A,Movimentacoes!$D:$D,A14),"") -> 46252 | S14: =IF(Q14="","",TODAY()-Q14) -> 7 | T14: =IF(F14<=0,"Ruptura",IF(F14<G14,"Abaixo do Minimo",IF(F14<M14,"Ponto de Reposicao","Normal"))) -> Normal | U14: =IF(AND(J14="Critico",P14<K14),"Alto",IF(P14<K14,"Medio","Baixo")) -> Baixo | V14: =SUMPRODUCT(($O$2:$O$46>=O14)*$O$2:$O$46)/SUM($O$2:$O$46) -> 0.82680978 | W14: =IF(V14<=0.7,"A",IF(V14<=0.9,"B","C")) -> B
... A46: 6004 | B46: Valvula Direcional | C46: Hidraulico | D46: UN | E46: 2650 | F46: =SUMIFS(Movimentacoes!$H:$H, Movimentacoes!$D:$D, A46) -> 265 | G46: =IFERROR(L48*(K48*1.1),"") -> 0 | H46: =IFERROR((G48+L48)*K48,"") -> 0 | I46: C-02-04 | J46: Nao Critico | K46: =AVERAGEIFS(Pedidos!$O:$O,Pedidos!$A:$A,A46,Pedidos!$L:$L,"Recebido") -> 7 | L46: =ROUND(ABS(SUMIFS(Movimentacoes!$H:$H,Movimentacoes!$D:$D,A46,Movimentacoes!$C:$C,"261"))/MAX(1,DATEDIF(_xlfn.MINIFS(Movimentacoes!$A:$A,Movimentacoes!$D:$D,A46,Movimentacoes!$C:$C,"261"),_xlfn.MAXIFS(Movimentacoes!$A:$A,Movimentacoes!$D:$D,A46,Movimentacoes!$C:$C,"261"),"d")),1) -> 1.2 | M46: =IFERROR(G48+(L48*K48),"") -> 0 | N46: =IFERROR(H48-G48,"") -> 0 | O46: =F46*E46 -> 702250 | P46: =IFERROR(ROUND(F46/L46,1),0) -> 220.8 | Q46: =IFERROR(_xlfn.MAXIFS(Movimentacoes!$A:$A,Movimentacoes!$D:$D,A46),"") -> 46256 | S46: =IF(Q46="","",TODAY()-Q46) -> 3 | T46: =IF(F46<=0,"Ruptura",IF(F46<G46,"Abaixo do Minimo",IF(F46<M46,"Ponto de Reposicao","Normal"))) -> Normal | U46: =IF(AND(J46="Critico",P46<K46),"Alto",IF(P46<K46,"Medio","Baixo")) -> Baixo | V46: =SUMPRODUCT(($O$2:$O$46>=O46)*$O$2:$O$46)/SUM($O$2:$O$46) -> 0.79638679 | W46: =IF(V46<=0.7,"A",IF(V46<=0.9,"B","C")) -> B
R47: =IF( (INDEX(Movimentacoes!$A:$A, MATCH(A2, Movimentacoes!$D:$D, 0)) = LOOKUP(2, 1/(Movimentacoes!$D:$D=A2), Movimentacoes!$A:$A)), 0, ABS(SUMIFS(Movimentacoes!$H:$H, Movimentacoes!$D:$D, Materiais!A2, Movimentacoes!$C:$C, "261")) /(( (INDEX(Movimentacoes!$I:$I, MATCH(A2, Movimentacoes!$D:$D, 0)) - INDEX(Movimentacoes!$H:$H, MATCH(A2, Movimentacoes!$D:$D, 0))) + LOOKUP(2, 1/(Movimentacoes!$D:$D=A2), Movimentacoes!$I:$I) ) / 2) * (365 / (LOOKUP(2, 1/(Movimentacoes!$D:$D=A2), Movimentacoes!$A:$A) - INDEX(Movimentacoes!$A:$A, MATCH(A2, Movimentacoes!$D:$D, 0))) ) ) -> 21.312948

Sheet Fornecedores
A1: Codigo | B1: Nome do Fornecedor | C1: Contato | D1: Lead Time Medio (dias) | E1: Total de Pedidos | F1: Pedidos Recebidos | G1: Entregas no Prazo | H1: % OTIF | I1: Pedidos Atrasados (Abertos) | J1: Performance
A2: {=IFERROR(INDEX(Pedidos!$E$2:$E$10000,MATCH(0,COUNTIF($A$1:A1,Pedidos!$E$2:$E$10000),0)),"")} -> FORN-001 | B2: =IFERROR(VLOOKUP(A2,Pedidos!$E:$F,2,FALSE),"") -> Metso Outotec Brasil | C2: (11) 4002-8888 | D2: =ROUND(AVERAGEIF(Pedidos!$E:$E,A2,Pedidos!$O:$O),0) -> 5 | E2: =COUNTIF(Pedidos!$E:$E,Fornecedores!A2) -> 27 | F2: =COUNTIFS(Pedidos!$E:$E,Fornecedores!A2,Pedidos!$L:$L,"Recebido") -> 18 | G2: =COUNTIFS(Pedidos!$E:$E,A2,Pedidos!$M:$M,"No Prazo") -> 18 | H2: =IFERROR(G2/F2,0) -> 1 | I2: =COUNTIFS(Pedidos!$E:$E,A2,Pedidos!$L:$L,"Atrasado") -> 5 | J2: =IF(H2>=0.95,"Excelente",IF(H2>=0.85,"Bom",IF(H2>=0.7,"Regular","Ruim"))) -> Excelente
A3: {=IFERROR(INDEX(Pedidos!$E$2:$E$10000,MATCH(0,COUNTIF($A$1:A2,Pedidos!$E$2:$E$10000),0)),"")} -> FORN-002 | B3: =IFERROR(VLOOKUP(A3,Pedidos!$E:$F,2,FALSE),"") -> SKF do Brasil Ltda | C3: (31) 3298-1000 | D3: =ROUND(AVERAGEIF(Pedidos!$E:$E,A3,Pedidos!$O:$O),0) -> 8 | E3: =COUNTIF(Pedidos!$E:$E,Fornecedores!A3) -> 28 | F3: =COUNTIFS(Pedidos!$E:$E,Fornecedores!A3,Pedidos!$L:$L,"Recebido") -> 18 | G3: =COUNTIFS(Pedidos!$E:$E,A3,Pedidos!$M:$M,"No Prazo") -> 13 | H3: =IFERROR(G3/F3,0) -> 0.72222222 | I3: =COUNTIFS(Pedidos!$E:$E,A3,Pedidos!$L:$L,"Atrasado") -> 7 | J3: =IF(H3>=0.95,"Excelente",IF(H3>=0.85,"Bom",IF(H3>=0.7,"Regular","Ruim"))) -> Regular
A4: {=IFERROR(INDEX(Pedidos!$E$2:$E$10000,MATCH(0,COUNTIF($A$1:A3,Pedidos!$E$2:$E$10000),0)),"")} -> FORN-003 | B4: =IFERROR(VLOOKUP(A4,Pedidos!$E:$F,2,FALSE),"") -> WEG Equipamentos Eletricos | C4: (11) 5185-4000 | D4: =ROUND(AVERAGEIF(Pedidos!$E:$E,A4,Pedidos!$O:$O),0) -> 7 | E4: =COUNTIF(Pedidos!$E:$E,Fornecedores!A4) -> 27 | F4: =COUNTIFS(Pedidos!$E:$E,Fornecedores!A4,Pedidos!$L:$L,"Recebido") -> 18 | G4: =COUNTIFS(Pedidos!$E:$E,A4,Pedidos!$M:$M,"No Prazo") -> 14 | H4: =IFERROR(G4/F4,0) -> 0.77777778 | I4: =COUNTIFS(Pedidos!$E:$E,A4,Pedidos!$L:$L,"Atrasado") -> 7 | J4: =IF(H4>=0.95,"Excelente",IF(H4>=0.85,"Bom",IF(H4>=0.7,"Regular","Ruim"))) -> Regular
A5: {=IFERROR(INDEX(Pedidos!$E$2:$E$10000,MATCH(0,COUNTIF($A$1:A4,Pedidos!$E$2:$E$10000),0)),"")} -> FORN-004 | B5: =IFERROR(VLOOKUP(A5,Pedidos!$E:$F,2,FALSE),"") -> Parker Hannifin Ind. e Com. | C5: (47) 3276-4000 | D5: =ROUND(AVERAGEIF(Pedidos!$E:$E,A5,Pedidos!$O:$O),0) -> 8 | E5: =COUNTIF(Pedidos!$E:$E,Fornecedores!A5) -> 27 | F5: =COUNTIFS(Pedidos!$E:$E,Fornecedores!A5,Pedidos!$L:$L,"Recebido") -> 18 | G5: =COUNTIFS(Pedidos!$E:$E,A5,Pedidos!$M:$M,"No Prazo") -> 15 | H5: =IFERROR(G5/F5,0) -> 0.83333333 | I5: =COUNTIFS(Pedidos!$E:$E,A5,Pedidos!$L:$L,"Atrasado") -> 9 | J5: =IF(H5>=0.95,"Excelente",IF(H5>=0.85,"Bom",IF(H5>=0.7,"Regular","Ruim"))) -> Regular
A6: {=IFERROR(INDEX(Pedidos!$E$2:$E$10000,MATCH(0,COUNTIF($A$1:A5,Pedidos!$E$2:$E$10000),0)),"")} -> FORN-005 | B6: =IFERROR(VLOOKUP(A6,Pedidos!$E:$F,2,FALSE),"") -> Continental Correias Ind. | C6: (19) 3876-5500 | D6: =ROUND(AVERAGEIF(Pedidos!$E:$E,A6,Pedidos!$O:$O),0) -> 7 | E6: =COUNTIF(Pedidos!$E:$E,Fornecedores!A6) -> 27 | F6: =COUNTIFS(Pedidos!$E:$E,Fornecedores!A6,Pedidos!$L:$L,"Recebido") -> 18 | G6: =COUNTIFS(Pedidos!$E:$E,A6,Pedidos!$M:$M,"No Prazo") -> 17 | H6: =IFERROR(G6/F6,0) -> 0.94444444 | I6: =COUNTIFS(Pedidos!$E:$E,A6,Pedidos!$L:$L,"Atrasado") -> 8 | J6: =IF(H6>=0.95,"Excelente",IF(H6>=0.85,"Bom",IF(H6>=0.7,"Regular","Ruim"))) -> Bom
B7: =IFERROR(VLOOKUP(A7,Pedidos!$E:$F,2,FALSE),"")
A8: {=IFERROR(INDEX(Pedidos!$E$2:$E$135,MATCH(0,COUNTIF($A$1:A7,Pedidos!$E$2:$E$135),0)),"")} | B8: =IFERROR(VLOOKUP(A8,Pedidos!$E:$F,2,FALSE),"")
A9: {=IFERROR(INDEX(Pedidos!$E$2:$E$135,MATCH(0,COUNTIF($A$1:A8,Pedidos!$E$2:$E$135),0)),"")} | B9: =IFERROR(VLOOKUP(A9,Pedidos!$E:$F,2,FALSE),"")

Sheet Movimentacoes
A1: Data | B1: Documento Material | C1: Tipo Movimento | D1: Cod Material | E1: Material | F1: Centro | G1: Deposito | H1: Quantidade | I1: Saldo Atual | J1: UM | K1: Valor Unitario | L1: Valor Total | M1: Referencia
A2: 45664 | B2: 500000001 | C2: 101 | D2: 2001 | E2: Mandibula Fixa do Britador | F2: 1000 | G2: ALM1 | H2: 52 | I2: =SUMIF($D$2:D2, D2, $H$2:H2) -> 52 | J2: UN | K2: 18500 | L2: =ABS(Tabela4[[#This Row],[Quantidade]]*Tabela4[[#This Row],[Valor Unitario]]) -> 962000 | M2: Pedido 450001001
A3: 45668 | B3: 500000017 | C3: 101 | D3: 2002 | E3: Mandibula Movel do Britador | F3: 1000 | G3: ALM1 | H3: 59 | I3: =SUMIF($D$2:D3, D3, $H$2:H3) -> 59 | J3: UN | K3: 19800 | L3: =ABS(Tabela4[[#This Row],[Quantidade]]*Tabela4[[#This Row],[Valor Unitario]]) -> 1168200 | M3: Pedido 450001009
A4: 45669 | B4: 500000033 | C4: 101 | D4: 2003 | E4: Revestimento Concavo | F4: 1000 | G4: ALM1 | H4: 60 | I4: =SUMIF($D$2:D4, D4, $H$2:H4) -> 60 | J4: UN | K4: 12400 | L4: =ABS(Tabela4[[#This Row],[Quantidade]]*Tabela4[[#This Row],[Valor Unitario]]) -> 744000 | M4: Pedido 450001017
A5: 45678 | B5: 500000034 | C5: 261 | D5: 2003 | E5: Revestimento Concavo | F5: 1000 | G5: ALM1 | H5: -44 | I5: =SUMIF($D$2:D5, D5, $H$2:H5) -> 16 | J5: UN | K5: 12400 | L5: =ABS(Tabela4[[#This Row],[Quantidade]]*Tabela4[[#This Row],[Valor Unitario]]) -> 545600 | M5: OS 70001017
A6: 45681 | B6: 500000018 | C6: 261 | D6: 2002 | E6: Mandibula Movel do Britador | F6: 1000 | G6: ALM1 | H6: -6 | I6: =SUMIF($D$2:D6, D6, $H$2:H6) -> 53 | J6: UN | K6: 19800 | L6: =ABS(Tabela4[[#This Row],[Quantidade]]*Tabela4[[#This Row],[Valor Unitario]]) -> 118800 | M6: OS 70001009
A7: 45686 | B7: 500000002 | C7: 261 | D7: 2001 | E7: Mandibula Fixa do Britador | F7: 1000 | G7: ALM1 | H7: -20 | I7: =SUMIF($D$2:D7, D7, $H$2:H7) -> 32 | J7: UN | K7: 18500 | L7: =ABS(Tabela4[[#This Row],[Quantidade]]*Tabela4[[#This Row],[Valor Unitario]]) -> 370000 | M7: OS 70001001
A8: 45700 | B8: 500000019 | C8: 101 | D8: 2002 | E8: Mandibula Movel do Britador | F8: 1000 | G8: ALM1 | H8: 80 | I8: =SUMIF($D$2:D8, D8, $H$2:H8) -> 133 | J8: UN | K8: 19800 | L8: =ABS(Tabela4[[#This Row],[Quantidade]]*Tabela4[[#This Row],[Valor Unitario]]) -> 1584000 | M8: Pedido 450001010
A9: 45701 | B9: 500000003 | C9: 101 | D9: 2001 | E9: Mandibula Fixa do Britador | F9: 1000 | G9: ALM1 | H9: 21 | I9: =SUMIF($D$2:D9, D9, $H$2:H9) -> 53 | J9: UN | K9: 18500 | L9: =ABS(Tabela4[[#This Row],[Quantidade]]*Tabela4[[#This Row],[Valor Unitario]]) -> 388500 | M9: Pedido 450001002
A10: 45701 | B10: 500000035 | C10: 101 | D10: 2003 | E10: Revestimento Concavo | F10: 1000 | G10: ALM1 | H10: 8 | I10: =SUMIF($D$2:D10, D10, $H$2:H10) -> 24 | J10: UN | K10: 12400 | L10: =ABS(Tabela4[[#This Row],[Quantidade]]*Tabela4[[#This Row],[Valor Unitario]]) -> 99200 | M10: Pedido 450001018
A11: 45705 | B11: 500000036 | C11: 261 | D11: 2003 | E11: Revestimento Concavo | F11: 1000 | G11: ALM1 | H11: -78 | I11: =SUMIF($D$2:D11, D11, $H$2:H11) -> -54 | J11: UN | K11: 12400 | L11: =ABS(Tabela4[[#This Row],[Quantidade]]*Tabela4[[#This Row],[Valor Unitario]]) -> 967200 | M11: OS 70001018
A12: 45709 | B12: 500000004 | C12: 261 | D12: 2001 | E12: Mandibula Fixa do Britador | F12: 1000 | G12: ALM1 | H12: -15 | I12: =SUMIF($D$2:D12, D12, $H$2:H12) -> 38 | J12: UN | K12: 18500 | L12: =ABS(Tabela4[[#This Row],[Quantidade]]*Tabela4[[#This Row],[Valor Unitario]]) -> 277500 | M12: OS 70001002
A13: 45716 | B13: 500000020 | C13: 261 | D13: 2002 | E13: Mandibula Movel do Britador | F13: 1000 | G13: ALM1 | H13: -7 | I13: =SUMIF($D$2:D13, D13, $H$2:H13) -> 126 | J13: UN | K13: 19800 | L13: =ABS(Tabela4[[#This Row],[Quantidade]]*Tabela4[[#This Row],[Valor Unitario]]) -> 138600 | M13: OS 70001010
... A721: 46257 | B721: 500000624 | C721: 261 | D721: 8001 | E721: Oleo Lubrificante ISO 220 | F721: 1000 | G721: ALM1 | H721: -53 | I721: =SUMIF($D$2:D721, D721, $H$2:H721) -> 55 | J721: L | K721: 28 | L721: =ABS(Tabela4[[#This Row],[Quantidade]]*Tabela4[[#This Row],[Valor Unitario]]) -> 1484 | M721: OS 70001312

Sheet Requisicoes
A1: Cod Material | B1: Material | C1: Requisição | D1: Cod Fornecedor | E1: Fornecedor | F1: Data | G1: Quantidade | H1: Status | I1: Dias em Aberto
A2: 2005 | B2: =IFERROR(INDEX(Materiais!$B:$B,MATCH(A2,Materiais!$A:$A,0)),"") -> Chapa Blindada Lateral | C2: 450002304 | D2: FORN-005 | E2: Continental Correias Ind. | F2: 46218 | G2: 8 | H2: Convertida | I2: =IF(H2="Convertida","-",TODAY()-F2) -> -
A3: 2011 | B3: =IFERROR(INDEX(Materiais!$B:$B,MATCH(A3,Materiais!$A:$A,0)),"") -> Volante de Inercia | C3: 450002310 | D3: FORN-005 | E3: Continental Correias Ind. | F3: 46194 | G3: 2 | H3: Convertida | I3: =IF(H3="Convertida","-",TODAY()-F3) -> -
A4: 2360 | B4: =IFERROR(INDEX(Materiais!$B:$B,MATCH(A4,Materiais!$A:$A,0)),"") -> Rolamento Autocompensador 22222 | C4: 450002316 | D4: FORN-005 | E4: Continental Correias Ind. | F4: 46190 | G4: 7 | H4: Convertida | I4: =IF(H4="Convertida","-",TODAY()-F4) -> -
A5: 4001 | B5: =IFERROR(INDEX(Materiais!$B:$B,MATCH(A5,Materiais!$A:$A,0)),"") -> Mola de Compressao | C5: 450002322 | D5: FORN-005 | E5: Continental Correias Ind. | F5: 46199 | G5: 3 | H5: Em Cotacao | I5: =IF(H5="Convertida","-",TODAY()-F5) -> 60
A6: 2006 | B6: =IFERROR(INDEX(Materiais!$B:$B,MATCH(A6,Materiais!$A:$A,0)),"") -> Chapa de Desgaste | C6: 450002305 | D6: FORN-001 | E6: Metso Outotec Brasil | F6: 46221 | G6: 2 | H6: Pendente | I6: =IF(H6="Convertida","-",TODAY()-F6) -> 38
A7: 2001 | B7: =IFERROR(INDEX(Materiais!$B:$B,MATCH(A7,Materiais!$A:$A,0)),"") -> Mandibula Fixa do Britador | C7: 450002300 | D7: FORN-001 | E7: Metso Outotec Brasil | F7: 45834 | G7: 8 | H7: Convertida | I7: =IF(H7="Convertida","-",TODAY()-F7) -> -
A8: 2007 | B8: =IFERROR(INDEX(Materiais!$B:$B,MATCH(A8,Materiais!$A:$A,0)),"") -> Placa de Impacto | C8: 450002306 | D8: FORN-001 | E8: Metso Outotec Brasil | F8: 46146 | G8: 4 | H8: Pendente | I8: =IF(H8="Convertida","-",TODAY()-F8) -> 113
A9: 2009 | B9: =IFERROR(INDEX(Materiais!$B:$B,MATCH(A9,Materiais!$A:$A,0)),"") -> Bucha de Bronze | C9: 450002308 | D9: FORN-003 | E9: WEG Equipamentos Eletricos | F9: 46208 | G9: 5 | H9: Pendente | I9: =IF(H9="Convertida","-",TODAY()-F9) -> 51
A10: 2012 | B10: =IFERROR(INDEX(Materiais!$B:$B,MATCH(A10,Materiais!$A:$A,0)),"") -> Grelha Vibratoria | C10: 450002311 | D10: FORN-001 | E10: Metso Outotec Brasil | F10: 46182 | G10: 5 | H10: Convertida | I10: =IF(H10="Convertida","-",TODAY()-F10) -> -
A11: 2356 | B11: =IFERROR(INDEX(Materiais!$B:$B,MATCH(A11,Materiais!$A:$A,0)),"") -> Rolamento 6205 | C11: 450002312 | D11: FORN-001 | E11: Metso Outotec Brasil | F11: 46150 | G11: 2 | H11: Em Cotacao | I11: =IF(H11="Convertida","-",TODAY()-F11) -> 109
A12: 2361 | B12: =IFERROR(INDEX(Materiais!$B:$B,MATCH(A12,Materiais!$A:$A,0)),"") -> Retentor de Vedacao | C12: 450002317 | D12: FORN-001 | E12: Metso Outotec Brasil | F12: 46151 | G12: 4 | H12: Em Cotacao | I12: =IF(H12="Convertida","-",TODAY()-F12) -> 108
A13: 3001 | B13: =IFERROR(INDEX(Materiais!$B:$B,MATCH(A13,Materiais!$A:$A,0)),"") -> Correia Transportadora B-1200 | C13: 450002318 | D13: FORN-001 | E13: Metso Outotec Brasil | F13: 46185 | G13: 6 | H13: Pendente | I13: =IF(H13="Convertida","-",TODAY()-F13) -> 74
... A32: 5005 | B32: =IFERROR(INDEX(Materiais!$B:$B,MATCH(A32,Materiais!$A:$A,0)),"") -> Sensor de Temperatura | C32: 450002329 | D32: FORN-003 | E32: WEG Equipamentos Eletricos | F32: 46151 | G32: 4 | H32: Pendente | I32: =IF(H32="Convertida","-",TODAY()-F32) -> 108

Sheet Pedidos
A1: Cod Material | B1: Material | C1: Pedido | D1: Data Emissao | E1: Cod Fornecedor | F1: Fornecedor | G1: Quantidade | H1: Valor Unitario | I1: Valor Total | J1: Data Prevista | K1: Data Recebimento | L1: Status | M1: Situacao Entrega | N1: Dias de Atraso | O1: Lead Time
A2: 2009 | B2: Bucha de Bronze | C2: 45000126 | D2: 46239 | E2: FORN-001 | F2: Metso Outotec Brasil | G2: 79 | H2: 1650 | I2: =Tabela3[[#This Row],[Quantidade]]*Tabela3[[#This Row],[Valor Unitario]] -> 130350 | J2: 46246 | L2: =IF(K2<>"","Recebido",IF(TODAY()>J2,"Atrasado","Em Transito")) -> Atrasado | M2: =IF(K2="","",IF(K2<=J2,"No Prazo","Atrasado")) | N2: =IF(Tabela3[[#This Row],[Data Recebimento]]="","",Tabela3[[#This Row],[Data Recebimento]]-Tabela3[[#This Row],[Data Prevista]]) | O2: =IF(Tabela3[[#This Row],[Data Recebimento]]="","",Tabela3[[#This Row],[Data Recebimento]]-Tabela3[[#This Row],[Data Emissao]])
A3: 2002 | B3: Mandibula Movel do Britador | C3: 45000103 | D3: 45665 | E3: FORN-002 | F3: SKF do Brasil Ltda | G3: 63 | H3: 19800 | I3: =Tabela3[[#This Row],[Quantidade]]*Tabela3[[#This Row],[Valor Unitario]] -> 1247400 | J3: 45672 | K3: 45675 | L3: =IF(K3<>"","Recebido",IF(TODAY()>J3,"Atrasado","Em Transito")) -> Recebido | M3: =IF(K3="","",IF(K3<=J3,"No Prazo","Atrasado")) -> Atrasado | N3: =IF(Tabela3[[#This Row],[Data Recebimento]]="","",Tabela3[[#This Row],[Data Recebimento]]-Tabela3[[#This Row],[Data Prevista]]) -> 3 | O3: =IF(Tabela3[[#This Row],[Data Recebimento]]="","",Tabela3[[#This Row],[Data Recebimento]]-Tabela3[[#This Row],[Data Emissao]]) -> 10
A4: 2001 | B4: Mandibula Fixa do Britador | C4: 45000102 | D4: 45874 | E4: FORN-003 | F4: WEG Equipamentos Eletricos | G4: 87 | H4: 18500 | I4: =Tabela3[[#This Row],[Quantidade]]*Tabela3[[#This Row],[Valor Unitario]] -> 1609500 | J4: 45881 | L4: =IF(K4<>"","Recebido",IF(TODAY()>J4,"Atrasado","Em Transito")) -> Atrasado | M4: =IF(K4="","",IF(K4<=J4,"No Prazo","Atrasado")) | N4: =IF(Tabela3[[#This Row],[Data Recebimento]]="","",Tabela3[[#This Row],[Data Recebimento]]-Tabela3[[#This Row],[Data Prevista]]) | O4: =IF(Tabela3[[#This Row],[Data Recebimento]]="","",Tabela3[[#This Row],[Data Recebimento]]-Tabela3[[#This Row],[Data Emissao]])
A5: 2003 | B5: Revestimento Concavo | C5: 45000106 | D5: 45667 | E5: FORN-003 | F5: WEG Equipamentos Eletricos | G5: 68 | H5: 12400 | I5: =Tabela3[[#This Row],[Quantidade]]*Tabela3[[#This Row],[Valor Unitario]] -> 843200 | J5: 45674 | K5: 45674 | L5: =IF(K5<>"","Recebido",IF(TODAY()>J5,"Atrasado","Em Transito")) -> Recebido | M5: =IF(K5="","",IF(K5<=J5,"No Prazo","Atrasado")) -> No Prazo | N5: =IF(Tabela3[[#This Row],[Data Recebimento]]="","",Tabela3[[#This Row],[Data Recebimento]]-Tabela3[[#This Row],[Data Prevista]]) -> 0 | O5: =IF(Tabela3[[#This Row],[Data Recebimento]]="","",Tabela3[[#This Row],[Data Recebimento]]-Tabela3[[#This Row],[Data Emissao]]) -> 7
A6: 2004 | B6: Revestimento Manto | C6: 45000109 | D6: 46065 | E6: FORN-004 | F6: Parker Hannifin Ind. e Com. | G6: 49 | H6: 11800 | I6: =Tabela3[[#This Row],[Quantidade]]*Tabela3[[#This Row],[Valor Unitario]] -> 578200 | J6: 46072 | K6: 46074 | L6: =IF(K6<>"","Recebido",IF(TODAY()>J6,"Atrasado","Em Transito")) -> Recebido | M6: =IF(K6="","",IF(K6<=J6,"No Prazo","Atrasado")) -> Atrasado | N6: =IF(Tabela3[[#This Row],[Data Recebimento]]="","",Tabela3[[#This Row],[Data Recebimento]]-Tabela3[[#This Row],[Data Prevista]]) -> 2 | O6: =IF(Tabela3[[#This Row],[Data Recebimento]]="","",Tabela3[[#This Row],[Data Recebimento]]-Tabela3[[#This Row],[Data Emissao]]) -> 9
A7: 2002 | B7: Mandibula Movel do Britador | C7: 45000105 | D7: 45839 | E7: FORN-004 | F7: Parker Hannifin Ind. e Com. | G7: 72 | H7: 19800 | I7: =Tabela3[[#This Row],[Quantidade]]*Tabela3[[#This Row],[Valor Unitario]] -> 1425600 | J7: 45846 | L7: =IF(K7<>"","Recebido",IF(TODAY()>J7,"Atrasado","Em Transito")) -> Atrasado | M7: =IF(K7="","",IF(K7<=J7,"No Prazo","Atrasado")) | N7: =IF(Tabela3[[#This Row],[Data Recebimento]]="","",Tabela3[[#This Row],[Data Recebimento]]-Tabela3[[#This Row],[Data Prevista]]) | O7: =IF(Tabela3[[#This Row],[Data Recebimento]]="","",Tabela3[[#This Row],[Data Recebimento]]-Tabela3[[#This Row],[Data Emissao]])
A8: 2005 | B8: Chapa Blindada Lateral | C8: 45000112 | D8: 46067 | E8: FORN-005 | F8: Continental Correias Ind. | G8: 30 | H8: 3450 | I8: =Tabela3[[#This Row],[Quantidade]]*Tabela3[[#This Row],[Valor Unitario]] -> 103500 | J8: 46074 | K8: 46074 | L8: =IF(K8<>"","Recebido",IF(TODAY()>J8,"Atrasado","Em Transito")) -> Recebido | M8: =IF(K8="","",IF(K8<=J8,"No Prazo","Atrasado")) -> No Prazo | N8: =IF(Tabela3[[#This Row],[Data Recebimento]]="","",Tabela3[[#This Row],[Data Recebimento]]-Tabela3[[#This Row],[Data Prevista]]) -> 0 | O8: =IF(Tabela3[[#This Row],[Data Recebimento]]="","",Tabela3[[#This Row],[Data Recebimento]]-Tabela3[[#This Row],[Data Emissao]]) -> 7
A9: 2357 | B9: Rolamento 6308 | C9: 45000141 | D9: 46069 | E9: FORN-001 | F9: Metso Outotec Brasil | G9: 67 | H9: 210 | I9: =Tabela3[[#This Row],[Quantidade]]*Tabela3[[#This Row],[Valor Unitario]] -> 14070 | J9: 46076 | L9: =IF(K9<>"","Recebido",IF(TODAY()>J9,"Atrasado","Em Transito")) -> Atrasado | M9: =IF(K9="","",IF(K9<=J9,"No Prazo","Atrasado")) | N9: =IF(Tabela3[[#This Row],[Data Recebimento]]="","",Tabela3[[#This Row],[Data Recebimento]]-Tabela3[[#This Row],[Data Prevista]]) | O9: =IF(Tabela3[[#This Row],[Data Recebimento]]="","",Tabela3[[#This Row],[Data Recebimento]]-Tabela3[[#This Row],[Data Emissao]])
A10: 2003 | B10: Revestimento Concavo | C10: 45000108 | D10: 45874 | E10: FORN-005 | F10: Continental Correias Ind. | G10: 34 | H10: 12400 | I10: =Tabela3[[#This Row],[Quantidade]]*Tabela3[[#This Row],[Valor Unitario]] -> 421600 | J10: 45881 | L10: =IF(K10<>"","Recebido",IF(TODAY()>J10,"Atrasado","Em Transito")) -> Atrasado | M10: =IF(K10="","",IF(K10<=J10,"No Prazo","Atrasado")) | N10: =IF(Tabela3[[#This Row],[Data Recebimento]]="","",Tabela3[[#This Row],[Data Recebimento]]-Tabela3[[#This Row],[Data Prevista]]) | O10: =IF(Tabela3[[#This Row],[Data Recebimento]]="","",Tabela3[[#This Row],[Data Recebimento]]-Tabela3[[#This Row],[Data Emissao]])
A11: 2007 | B11: Placa de Impacto | C11: 45000118 | D11: 46099 | E11: FORN-002 | F11: SKF do Brasil Ltda | G11: 17 | H11: 1980 | I11: =Tabela3[[#This Row],[Quantidade]]*Tabela3[[#This Row],[Valor Unitario]] -> 33660 | J11: 46106 | K11: 46106 | L11: =IF(K11<>"","Recebido",IF(TODAY()>J11,"Atrasado","Em Transito")) -> Recebido | M11: =IF(K11="","",IF(K11<=J11,"No Prazo","Atrasado")) -> No Prazo | N11: =IF(Tabela3[[#This Row],[Data Recebimento]]="","",Tabela3[[#This Row],[Data Recebimento]]-Tabela3[[#This Row],[Data Prevista]]) -> 0 | O11: =IF(Tabela3[[#This Row],[Data Recebimento]]="","",Tabela3[[#This Row],[Data Recebimento]]-Tabela3[[#This Row],[Data Emissao]]) -> 7
A12: 2008 | B12: Eixo Excentrico | C12: 45000121 | D12: 46100 | E12: FORN-003 | F12: WEG Equipamentos Eletricos | G12: 46 | H12: 24500 | I12: =Tabela3[[#This Row],[Quantidade]]*Tabela3[[#This Row],[Valor Unitario]] -> 1127000 | J12: 46107 | K12: 46109 | L12: =IF(K12<>"","Recebido",IF(TODAY()>J12,"Atrasado","Em Transito")) -> Recebido | M12: =IF(K12="","",IF(K12<=J12,"No Prazo","Atrasado")) -> Atrasado | N12: =IF(Tabela3[[#This Row],[Data Recebimento]]="","",Tabela3[[#This Row],[Data Recebimento]]-Tabela3[[#This Row],[Data Prevista]]) -> 2 | O12: =IF(Tabela3[[#This Row],[Data Recebimento]]="","",Tabela3[[#This Row],[Data Recebimento]]-Tabela3[[#This Row],[Data Emissao]]) -> 9
A13: 3001 | B13: Correia Transportadora B-1200 | C13: 45000156 | D13: 46218 | E13: FORN-001 | F13: Metso Outotec Brasil | G13: 73 | H13: 320 | I13: =Tabela3[[#This Row],[Quantidade]]*Tabela3[[#This Row],[Valor Unitario]] -> 23360 | J13: 46225 | L13: =IF(K13<>"","Recebido",IF(TODAY()>J13,"Atrasado","Em Transito")) -> Atrasado | M13: =IF(K13="","",IF(K13<=J13,"No Prazo","Atrasado")) | N13: =IF(Tabela3[[#This Row],[Data Recebimento]]="","",Tabela3[[#This Row],[Data Recebimento]]-Tabela3[[#This Row],[Data Prevista]]) | O13: =IF(Tabela3[[#This Row],[Data Recebimento]]="","",Tabela3[[#This Row],[Data Recebimento]]-Tabela3[[#This Row],[Data Emissao]])
A14: 2009 | B14: Bucha de Bronze | C14: 45000124 | D14: 46098 | E14: FORN-004 | F14: Parker Hannifin Ind. e Com. | G14: 19 | H14: 1650 | I14: =Tabela3[[#This Row],[Quantidade]]*Tabela3[[#This Row],[Valor Unitario]] -> 31350 | J14: 46105 | K14: 46105 | L14: =IF(K14<>"","Recebido",IF(TODAY()>J14,"Atrasado","Em Transito")) -> Recebido | M14: =IF(K14="","",IF(K14<=J14,"No Prazo","Atrasado")) -> No Prazo | N14: =IF(Tabela3[[#This Row],[Data Recebimento]]="","",Tabela3[[#This Row],[Data Recebimento]]-Tabela3[[#This Row],[Data Prevista]]) -> 0 | O14: =IF(Tabela3[[#This Row],[Data Recebimento]]="","",Tabela3[[#This Row],[Data Recebimento]]-Tabela3[[#This Row],[Data Emissao]]) -> 7
A15: 2010 | B15: Bucha Excentrica | C15: 45000127 | D15: 46127 | E15: FORN-005 | F15: Continental Correias Ind. | G15: 22 | H15: 2150 | I15: =Tabela3[[#This Row],[Quantidade]]*Tabela3[[#This Row],[Valor Unitario]] -> 47300 | J15: 46134 | K15: 46134 | L15: =IF(K15<>"","Recebido",IF(TODAY()>J15,"Atrasado","Em Transito")) -> Recebido | M15: =IF(K15="","",IF(K15<=J15,"No Prazo","Atrasado")) -> No Prazo | N15: =IF(Tabela3[[#This Row],[Data Recebimento]]="","",Tabela3[[#This Row],[Data Recebimento]]-Tabela3[[#This Row],[Data Prevista]]) -> 0 | O15: =IF(Tabela3[[#This Row],[Data Recebimento]]="","",Tabela3[[#This Row],[Data Recebimento]]-Tabela3[[#This Row],[Data Emissao]]) -> 7
A16: 2005 | B16: Chapa Blindada Lateral | C16: 45000114 | D16: 46239 | E16: FORN-002 | F16: SKF do Brasil Ltda | G16: 80 | H16: 3450 | I16: =Tabela3[[#This Row],[Quantidade]]*Tabela3[[#This Row],[Valor Unitario]] -> 276000 | J16: 46246 | L16: =IF(K16<>"","Recebido",IF(TODAY()>J16,"Atrasado","Em Transito")) -> Atrasado | M16: =IF(K16="","",IF(K16<=J16,"No Prazo","Atrasado")) | N16: =IF(Tabela3[[#This Row],[Data Recebimento]]="","",Tabela3[[#This Row],[Data Recebimento]]-Tabela3[[#This Row],[Data Prevista]]) | O16: =IF(Tabela3[[#This Row],[Data Recebimento]]="","",Tabela3[[#This Row],[Data Recebimento]]-Tabela3[[#This Row],[Data Emissao]])
A17: 5005 | B17: Sensor de Temperatura | C17: 45000186 | D17: 46032 | E17: FORN-001 | F17: Metso Outotec Brasil | G17: 75 | H17: 780 | I17: =Tabela3[[#This Row],[Quantidade]]*Tabela3[[#This Row],[Valor Unitario]] -> 58500 | J17: 46039 | L17: =IF(K17<>"","Recebido",IF(TODAY()>J17,"Atrasado","Em Transito")) -> Atrasado | M17: =IF(K17="","",IF(K17<=J17,"No Prazo","Atrasado")) | N17: =IF(Tabela3[[#This Row],[Data Recebimento]]="","",Tabela3[[#This Row],[Data Recebimento]]-Tabela3[[#This Row],[Data Prevista]]) | O17: =IF(Tabela3[[#This Row],[Data Recebimento]]="","",Tabela3[[#This Row],[Data Recebimento]]-Tabela3[[#This Row],[Data Emissao]])
A18: 2012 | B18: Grelha Vibratoria | C18: 45000133 | D18: 46123 | E18: FORN-002 | F18: SKF do Brasil Ltda | G18: 17 | H18: 5400 | I18: =Tabela3[[#This Row],[Quantidade]]*Tabela3[[#This Row],[Valor Unitario]] -> 91800 | J18: 46130 | K18: 46134 | L18: =IF(K18<>"","Recebido",IF(TODAY()>J18,"Atrasado","Em Transito")) -> Recebido | M18: =IF(K18="","",IF(K18<=J18,"No Prazo","Atrasado")) -> Atrasado | N18: =IF(Tabela3[[#This Row],[Data Recebimento]]="","",Tabela3[[#This Row],[Data Recebimento]]-Tabela3[[#This Row],[Data Prevista]]) -> 4 | O18: =IF(Tabela3[[#This Row],[Data Recebimento]]="","",Tabela3[[#This Row],[Data Recebimento]]-Tabela3[[#This Row],[Data Emissao]]) -> 11
A19: 2006 | B19: Chapa de Desgaste | C19: 45000117 | D19: 46204 | E19: FORN-003 | F19: WEG Equipamentos Eletricos | G19: 29 | H19: 2870 | I19: =Tabela3[[#This Row],[Quantidade]]*Tabela3[[#This Row],[Valor Unitario]] -> 83230 | J19: 46273 | L19: =IF(K19<>"","Recebido",IF(TODAY()>J19,"Atrasado","Em Transito")) -> Em Transito | M19: =IF(K19="","",IF(K19<=J19,"No Prazo","Atrasado")) | N19: =IF(Tabela3[[#This Row],[Data Recebimento]]="","",Tabela3[[#This Row],[Data Recebimento]]-Tabela3[[#This Row],[Data Prevista]]) | O19: =IF(Tabela3[[#This Row],[Data Recebimento]]="","",Tabela3[[#This Row],[Data Recebimento]]-Tabela3[[#This Row],[Data Emissao]])
A20: 2356 | B20: Rolamento 6205 | C20: 45000136 | D20: 46151 | E20: FORN-003 | F20: WEG Equipamentos Eletricos | G20: 78 | H20: 145 | I20: =Tabela3[[#This Row],[Quantidade]]*Tabela3[[#This Row],[Valor Unitario]] -> 11310 | J20: 46158 | K20: 46158 | L20: =IF(K20<>"","Recebido",IF(TODAY()>J20,"Atrasado","Em Transito")) -> Recebido | M20: =IF(K20="","",IF(K20<=J20,"No Prazo","Atrasado")) -> No Prazo | N20: =IF(Tabela3[[#This Row],[Data Recebimento]]="","",Tabela3[[#This Row],[Data Recebimento]]-Tabela3[[#This Row],[Data Prevista]]) -> 0 | O20: =IF(Tabela3[[#This Row],[Data Recebimento]]="","",Tabela3[[#This Row],[Data Recebimento]]-Tabela3[[#This Row],[Data Emissao]]) -> 7
A21: 2357 | B21: Rolamento 6308 | C21: 45000139 | D21: 46149 | E21: FORN-004 | F21: Parker Hannifin Ind. e Com. | G21: 45 | H21: 210 | I21: =Tabela3[[#This Row],[Quantidade]]*Tabela3[[#This Row],[Valor Unitario]] -> 9450 | J21: 46156 | K21: 46156 | L21: =IF(K21<>"","Recebido",IF(TODAY()>J21,"Atrasado","Em Transito")) -> Recebido | M21: =IF(K21="","",IF(K21<=J21,"No Prazo","Atrasado")) -> No Prazo | N21: =IF(Tabela3[[#This Row],[Data Recebimento]]="","",Tabela3[[#This Row],[Data Recebimento]]-Tabela3[[#This Row],[Data Prevista]]) -> 0 | O21: =IF(Tabela3[[#This Row],[Data Recebimento]]="","",Tabela3[[#This Row],[Data Recebimento]]-Tabela3[[#This Row],[Data Emissao]]) -> 7
A22: 2007 | B22: Placa de Impacto | C22: 45000120 | D22: 46239 | E22: FORN-004 | F22: Parker Hannifin Ind. e Com. | G22: 24 | H22: 1980 | I22: =Tabela3[[#This Row],[Quantidade]]*Tabela3[[#This Row],[Valor Unitario]] -> 47520 | J22: 46246 | L22: =IF(K22<>"","Recebido",IF(TODAY()>J22,"Atrasado","Em Transito")) -> Atrasado | M22: =IF(K22="","",IF(K22<=J22,"No Prazo","Atrasado")) | N22: =IF(Tabela3[[#This Row],[Data Recebimento]]="","",Tabela3[[#This Row],[Data Recebimento]]-Tabela3[[#This Row],[Data Prevista]]) | O22: =IF(Tabela3[[#This Row],[Data Recebimento]]="","",Tabela3[[#This Row],[Data Recebimento]]-Tabela3[[#This Row],[Data Emissao]])
A23: 2358 | B23: Rolamento de Rolos Conicos 32218 | C23: 45000142 | D23: 46147 | E23: FORN-005 | F23: Continental Correias Ind. | G23: 54 | H23: 890 | I23: =Tabela3[[#This Row],[Quantidade]]*Tabela3[[#This Row],[Valor Unitario]] -> 48060 | J23: 46154 | K23: 46154 | L23: =IF(K23<>"","Recebido",IF(TODAY()>J23,"Atrasado","Em Transito")) -> Recebido | M23: =IF(K23="","",IF(K23<=J23,"No Prazo","Atrasado")) -> No Prazo | N23: =IF(Tabela3[[#This Row],[Data Recebimento]]="","",Tabela3[[#This Row],[Data Recebimento]]-Tabela3[[#This Row],[Data Prevista]]) -> 0 | O23: =IF(Tabela3[[#This Row],[Data Recebimento]]="","",Tabela3[[#This Row],[Data Recebimento]]-Tabela3[[#This Row],[Data Emissao]]) -> 7
A24: 8001 | B24: Oleo Lubrificante ISO 220 | C24: 45000216 | D24: 46098 | E24: FORN-001 | F24: Metso Outotec Brasil | G24: 87 | H24: 28 | I24: =Tabela3[[#This Row],[Quantidade]]*Tabela3[[#This Row],[Valor Unitario]] -> 2436 | J24: 46105 | L24: =IF(K24<>"","Recebido",IF(TODAY()>J24,"Atrasado","Em Transito")) -> Atrasado | M24: =IF(K24="","",IF(K24<=J24,"No Prazo","Atrasado")) | N24: =IF(Tabela3[[#This Row],[Data Recebimento]]="","",Tabela3[[#This Row],[Data Recebimento]]-Tabela3[[#This Row],[Data Prevista]]) | O24: =IF(Tabela3[[#This Row],[Data Recebimento]]="","",Tabela3[[#This Row],[Data Recebimento]]-Tabela3[[#This Row],[Data Emissao]])
A25: 2008 | B25: Eixo Excentrico | C25: 45000123 | D25: 46204 | E25: FORN-005 | F25: Continental Correias Ind. | G25: 33 | H25: 24500 | I25: =Tabela3[[#This Row],[Quantidade]]*Tabela3[[#This Row],[Valor Unitario]] -> 808500 | J25: 46273 | L25: =IF(K25<>"","Recebido",IF(TODAY()>J25,"Atrasado","Em Transito")) -> Em Transito | M25: =IF(K25="","",IF(K25<=J25,"No Prazo","Atrasado")) | N25: =IF(Tabela3[[#This Row],[Data Recebimento]]="","",Tabela3[[#This Row],[Data Recebimento]]-Tabela3[[#This Row],[Data Prevista]]) | O25: =IF(Tabela3[[#This Row],[Data Recebimento]]="","",Tabela3[[#This Row],[Data Recebimento]]-Tabela3[[#This Row],[Data Emissao]])
A26: 2360 | B26: Rolamento Autocompensador 22222 | C26: 45000148 | D26: 46174 | E26: FORN-002 | F26: SKF do Brasil Ltda | G26: 71 | H26: 2380 | I26: =Tabela3[[#This Row],[Quantidade]]*Tabela3[[#This Row],[Valor Unitario]] -> 168980 | J26: 46181 | K26: 46181 | L26: =IF(K26<>"","Recebido",IF(TODAY()>J26,"Atrasado","Em Transito")) -> Recebido | M26: =IF(K26="","",IF(K26<=J26,"No Prazo","Atrasado")) -> No Prazo | N26: =IF(Tabela3[[#This Row],[Data Recebimento]]="","",Tabela3[[#This Row],[Data Recebimento]]-Tabela3[[#This Row],[Data Prevista]]) -> 0 | O26: =IF(Tabela3[[#This Row],[Data Recebimento]]="","",Tabela3[[#This Row],[Data Recebimento]]-Tabela3[[#This Row],[Data Emissao]]) -> 7
A27: 2361 | B27: Retentor de Vedacao | C27: 45000151 | D27: 46183 | E27: FORN-003 | F27: WEG Equipamentos Eletricos | G27: 32 | H27: 68 | I27: =Tabela3[[#This Row],[Quantidade]]*Tabela3[[#This Row],[Valor Unitario]] -> 2176 | J27: 46190 | K27: 46192 | L27: =IF(K27<>"","Recebido",IF(TODAY()>J27,"Atrasado","Em Transito")) -> Recebido | M27: =IF(K27="","",IF(K27<=J27,"No Prazo","Atrasado")) -> Atrasado | N27: =IF(Tabela3[[#This Row],[Data Recebimento]]="","",Tabela3[[#This Row],[Data Recebimento]]-Tabela3[[#This Row],[Data Prevista]]) -> 2 | O27: =IF(Tabela3[[#This Row],[Data Recebimento]]="","",Tabela3[[#This Row],[Data Recebimento]]-Tabela3[[#This Row],[Data Emissao]]) -> 9
A28: 2004 | B28: Revestimento Manto | C28: 45000111 | D28: 46204 | E28: FORN-001 | F28: Metso Outotec Brasil | G28: 44 | H28: 11800 | I28: =Tabela3[[#This Row],[Quantidade]]*Tabela3[[#This Row],[Valor Unitario]] -> 519200 | J28: 46273 | L28: =IF(K28<>"","Recebido",IF(TODAY()>J28,"Atrasado","Em Transito")) -> Em Transito | M28: =IF(K28="","",IF(K28<=J28,"No Prazo","Atrasado")) | N28: =IF(Tabela3[[#This Row],[Data Recebimento]]="","",Tabela3[[#This Row],[Data Recebimento]]-Tabela3[[#This Row],[Data Prevista]]) | O28: =IF(Tabela3[[#This Row],[Data Recebimento]]="","",Tabela3[[#This Row],[Data Recebimento]]-Tabela3[[#This Row],[Data Emissao]])
A29: 3001 | B29: Correia Transportadora B-1200 | C29: 45000154 | D29: 46221 | E29: FORN-004 | F29: Parker Hannifin Ind. e Com. | G29: 45 | H29: 320 | I29: =Tabela3[[#This Row],[Quantidade]]*Tabela3[[#This Row],[Valor Unitario]] -> 14400 | J29: 46228 | K29: 46228 | L29: =IF(K29<>"","Recebido",IF(TODAY()>J29,"Atrasado","Em Transito")) -> Recebido | M29: =IF(K29="","",IF(K29<=J29,"No Prazo","Atrasado")) -> No Prazo | N29: =IF(Tabela3[[#This Row],[Data Recebimento]]="","",Tabela3[[#This Row],[Data Recebimento]]-Tabela3[[#This Row],[Data Prevista]]) -> 0 | O29: =IF(Tabela3[[#This Row],[Data Recebimento]]="","",Tabela3[[#This Row],[Data Recebimento]]-Tabela3[[#This Row],[Data Emissao]]) -> 7
A30: 3002 | B30: Correia em V A-75 | C30: 45000157 | D30: 46222 | E30: FORN-005 | F30: Continental Correias Ind. | G30: 65 | H30: 95 | I30: =Tabela3[[#This Row],[Quantidade]]*Tabela3[[#This Row],[Valor Unitario]] -> 6175 | J30: 46229 | K30: 46229 | L30: =IF(K30<>"","Recebido",IF(TODAY()>J30,"Atrasado","Em Transito")) -> Recebido | M30: =IF(K30="","",IF(K30<=J30,"No Prazo","Atrasado")) -> No Prazo | N30: =IF(Tabela3[[#This Row],[Data Recebimento]]="","",Tabela3[[#This Row],[Data Recebimento]]-Tabela3[[#This Row],[Data Prevista]]) -> 0 | O30: =IF(Tabela3[[#This Row],[Data Recebimento]]="","",Tabela3[[#This Row],[Data Recebimento]]-Tabela3[[#This Row],[Data Emissao]]) -> 7
A31: 2010 | B31: Bucha Excentrica | C31: 45000129 | D31: 46070 | E31: FORN-002 | F31: SKF do Brasil Ltda | G31: 67 | H31: 2150 | I31: =Tabela3[[#This Row],[Quantidade]]*Tabela3[[#This Row],[Valor Unitario]] -> 144050 | J31: 46077 | L31: =IF(K31<>"","Recebido",IF(TODAY()>J31,"Atrasado","Em Transito")) -> Atrasado | M31: =IF(K31="","",IF(K31<=J31,"No Prazo","Atrasado")) | N31: =IF(Tabela3[[#This Row],[Data Recebimento]]="","",Tabela3[[#This Row],[Data Recebimento]]-Tabela3[[#This Row],[Data Prevista]]) | O31: =IF(Tabela3[[#This Row],[Data Recebimento]]="","",Tabela3[[#This Row],[Data Recebimento]]-Tabela3[[#This Row],[Data Emissao]])
A32: 4002 | B32: Amortecedor de Impacto | C32: 45000171 | D32: 46123 | E32: FORN-001 | F32: Metso Outotec Brasil | G32: 68 | H32: 4100 | I32: =Tabela3[[#This Row],[Quantidade]]*Tabela3[[#This Row],[Valor Unitario]] -> 278800 | J32: 46283 | L32: =IF(K32<>"","Recebido",IF(TODAY()>J32,"Atrasado","Em Transito")) -> Em Transito | M32: =IF(K32="","",IF(K32<=J32,"No Prazo","Atrasado")) | N32: =IF(Tabela3[[#This Row],[Data Recebimento]]="","",Tabela3[[#This Row],[Data Recebimento]]-Tabela3[[#This Row],[Data Prevista]]) | O32: =IF(Tabela3[[#This Row],[Data Recebimento]]="","",Tabela3[[#This Row],[Data Recebimento]]-Tabela3[[#This Row],[Data Emissao]])
A33: 3004 | B33: Polia Movida | C33: 45000163 | D33: 46247 | E33: FORN-002 | F33: SKF do Brasil Ltda | G33: 18 | H33: 2180 | I33: =Tabela3[[#This Row],[Quantidade]]*Tabela3[[#This Row],[Valor Unitario]] -> 39240 | J33: 46254 | K33: 46256 | L33: =IF(K33<>"","Recebido",IF(TODAY()>J33,"Atrasado","Em Transito")) -> Recebido | M33: =IF(K33="","",IF(K33<=J33,"No Prazo","Atrasado")) -> Atrasado | N33: =IF(Tabela3[[#This Row],[Data Recebimento]]="","",Tabela3[[#This Row],[Data Recebimento]]-Tabela3[[#This Row],[Data Prevista]]) -> 2 | O33: =IF(Tabela3[[#This Row],[Data Recebimento]]="","",Tabela3[[#This Row],[Data Recebimento]]-Tabela3[[#This Row],[Data Emissao]]) -> 9
A34: 2011 | B34: Volante de Inercia | C34: 45000132 | D34: 46064 | E34: FORN-003 | F34: WEG Equipamentos Eletricos | G34: 75 | H34: 9800 | I34: =Tabela3[[#This Row],[Quantidade]]*Tabela3[[#This Row],[Valor Unitario]] -> 735000 | J34: 46071 | L34: =IF(K34<>"","Recebido",IF(TODAY()>J34,"Atrasado","Em Transito")) -> Atrasado | M34: =IF(K34="","",IF(K34<=J34,"No Prazo","Atrasado")) | N34: =IF(Tabela3[[#This Row],[Data Recebimento]]="","",Tabela3[[#This Row],[Data Recebimento]]-Tabela3[[#This Row],[Data Prevista]]) | O34: =IF(Tabela3[[#This Row],[Data Recebimento]]="","",Tabela3[[#This Row],[Data Recebimento]]-Tabela3[[#This Row],[Data Emissao]])
A35: 4001 | B35: Mola de Compressao | C35: 45000166 | D35: 46243 | E35: FORN-003 | F35: WEG Equipamentos Eletricos | G35: 25 | H35: 3200 | I35: =Tabela3[[#This Row],[Quantidade]]*Tabela3[[#This Row],[Valor Unitario]] -> 80000 | J35: 46250 | K35: 46250 | L35: =IF(K35<>"","Recebido",IF(TODAY()>J35,"Atrasado","Em Transito")) -> Recebido | M35: =IF(K35="","",IF(K35<=J35,"No Prazo","Atrasado")) -> No Prazo | N35: =IF(Tabela3[[#This Row],[Data Recebimento]]="","",Tabela3[[#This Row],[Data Recebimento]]-Tabela3[[#This Row],[Data Prevista]]) -> 0 | O35: =IF(Tabela3[[#This Row],[Data Recebimento]]="","",Tabela3[[#This Row],[Data Recebimento]]-Tabela3[[#This Row],[Data Emissao]]) -> 7
A36: 4002 | B36: Amortecedor de Impacto | C36: 45000169 | D36: 46241 | E36: FORN-004 | F36: Parker Hannifin Ind. e Com. | G36: 18 | H36: 4100 | I36: =Tabela3[[#This Row],[Quantidade]]*Tabela3[[#This Row],[Valor Unitario]] -> 73800 | J36: 46248 | K36: 46248 | L36: =IF(K36<>"","Recebido",IF(TODAY()>J36,"Atrasado","Em Transito")) -> Recebido | M36: =IF(K36="","",IF(K36<=J36,"No Prazo","Atrasado")) -> No Prazo | N36: =IF(Tabela3[[#This Row],[Data Recebimento]]="","",Tabela3[[#This Row],[Data Recebimento]]-Tabela3[[#This Row],[Data Prevista]]) -> 0 | O36: =IF(Tabela3[[#This Row],[Data Recebimento]]="","",Tabela3[[#This Row],[Data Recebimento]]-Tabela3[[#This Row],[Data Emissao]]) -> 7
A37: 2012 | B37: Grelha Vibratoria | C37: 45000135 | D37: 46058 | E37: FORN-004 | F37: Parker Hannifin Ind. e Com. | G37: 39 | H37: 5400 | I37: =Tabela3[[#This Row],[Quantidade]]*Tabela3[[#This Row],[Valor Unitario]] -> 210600 | J37: 46065 | L37: =IF(K37<>"","Recebido",IF(TODAY()>J37,"Atrasado","Em Transito")) -> Atrasado | M37: =IF(K37="","",IF(K37<=J37,"No Prazo","Atrasado")) | N37: =IF(Tabela3[[#This Row],[Data Recebimento]]="","",Tabela3[[#This Row],[Data Recebimento]]-Tabela3[[#This Row],[Data Prevista]]) | O37: =IF(Tabela3[[#This Row],[Data Recebimento]]="","",Tabela3[[#This Row],[Data Recebimento]]-Tabela3[[#This Row],[Data Emissao]])
A38: 5001 | B38: Motor Eletrico 150cv | C38: 45000172 | D38: 46028 | E38: FORN-005 | F38: Continental Correias Ind. | G38: 67 | H38: 32500 | I38: =Tabela3[[#This Row],[Quantidade]]*Tabela3[[#This Row],[Valor Unitario]] -> 2177500 | J38: 46035 | K38: 46035 | L38: =IF(K38<>"","Recebido",IF(TODAY()>J38,"Atrasado","Em Transito")) -> Recebido | M38: =IF(K38="","",IF(K38<=J38,"No Prazo","Atrasado")) -> No Prazo | N38: =IF(Tabela3[[#This Row],[Data Recebimento]]="","",Tabela3[[#This Row],[Data Recebimento]]-Tabela3[[#This Row],[Data Prevista]]) -> 0 | O38: =IF(Tabela3[[#This Row],[Data Recebimento]]="","",Tabela3[[#This Row],[Data Recebimento]]-Tabela3[[#This Row],[Data Emissao]]) -> 7
A39: 6003 | B39: Mangueira Hidraulica 1 polegada | C39: 45000201 | D39: 46183 | E39: FORN-001 | F39: Metso Outotec Brasil | G39: 78 | H39: 85 | I39: =Tabela3[[#This Row],[Quantidade]]*Tabela3[[#This Row],[Valor Unitario]] -> 6630 | J39: 46282 | L39: =IF(K39<>"","Recebido",IF(TODAY()>J39,"Atrasado","Em Transito")) -> Em Transito | M39: =IF(K39="","",IF(K39<=J39,"No Prazo","Atrasado")) | N39: =IF(Tabela3[[#This Row],[Data Recebimento]]="","",Tabela3[[#This Row],[Data Recebimento]]-Tabela3[[#This Row],[Data Prevista]]) | O39: =IF(Tabela3[[#This Row],[Data Recebimento]]="","",Tabela3[[#This Row],[Data Recebimento]]-Tabela3[[#This Row],[Data Emissao]])
A40: 2356 | B40: Rolamento 6205 | C40: 45000138 | D40: 46032 | E40: FORN-005 | F40: Continental Correias Ind. | G40: 76 | H40: 145 | I40: =Tabela3[[#This Row],[Quantidade]]*Tabela3[[#This Row],[Valor Unitario]] -> 11020 | J40: 46039 | L40: =IF(K40<>"","Recebido",IF(TODAY()>J40,"Atrasado","Em Transito")) -> Atrasado | M40: =IF(K40="","",IF(K40<=J40,"No Prazo","Atrasado")) | N40: =IF(Tabela3[[#This Row],[Data Recebimento]]="","",Tabela3[[#This Row],[Data Recebimento]]-Tabela3[[#This Row],[Data Prevista]]) | O40: =IF(Tabela3[[#This Row],[Data Recebimento]]="","",Tabela3[[#This Row],[Data Recebimento]]-Tabela3[[#This Row],[Data Emissao]])
...

Sheet Indicadores
A1: 1. VALOR EM ESTOQUE POR CATEGORIA
A2: Categoria | B2: Valor (R$)
A3: {=IFERROR(INDEX(Materiais!$C$2:$C$10000,MATCH(0,COUNTIF($A$2:A2,Materiais!$C$2:$C$10000),0)),"")} -> Rolamentos | B3: =SUMIF(Materiais!$C:$C,A3,Materiais!$O:$O) -> 152164
A4: {=IFERROR(INDEX(Materiais!$C$2:$C$10000,MATCH(0,COUNTIF($A$2:A3,Materiais!$C$2:$C$10000),0)),"")} -> Estrutural | B4: =SUMIF(Materiais!$C:$C,A4,Materiais!$O:$O) -> 11180450
A5: {=IFERROR(INDEX(Materiais!$C$2:$C$10000,MATCH(0,COUNTIF($A$2:A4,Materiais!$C$2:$C$10000),0)),"")} -> Eletrico | B5: =SUMIF(Materiais!$C:$C,A5,Materiais!$O:$O) -> 4076148
A6: {=IFERROR(INDEX(Materiais!$C$2:$C$10000,MATCH(0,COUNTIF($A$2:A5,Materiais!$C$2:$C$10000),0)),"")} -> Correias e Polias | B6: =SUMIF(Materiais!$C:$C,A6,Materiais!$O:$O) -> 640230
